<?xml version="1.0" ?>
<!-- =================================================================================== -->
<!-- |    This document was autogenerated by xacro from robot.xacro                    | -->
<!-- |    EDITING THIS FILE BY HAND IS NOT RECOMMENDED                                 | -->
<!-- =================================================================================== -->
<robot name="wheel_legged">
  <material name="black">
    <color rgba="0.0 0.0 0.0 1.0"/>
  </material>
  <material name="blue">
    <color rgba="0.0 0.0 0.8 1.0"/>
  </material>
  <material name="green">
    <color rgba="0.0 0.8 0.0 1.0"/>
  </material>
  <material name="grey">
    <color rgba="0.2 0.2 0.2 1.0"/>
  </material>
  <material name="silver">
    <color rgba="0.9137254901960784 0.9137254901960784 0.8470588235294118 1.0"/>
  </material>
  <material name="orange">
    <color rgba="1.0 0.4235294117647059 0.0392156862745098 1.0"/>
  </material>
  <material name="brown">
    <color rgba="0.8705882352941177 0.8117647058823529 0.7647058823529411 1.0"/>
  </material>
  <material name="red">
    <color rgba="0.8 0.0 0.0 1.0"/>
  </material>
  <material name="white">
    <color rgba="1.0 1.0 1.0 1.0"/>
  </material>
  <!-- ros_control plugin -->
  <gazebo>
    <plugin filename="libwheellegged_hw_sim.so" name="gazebo_ros_control">
      <robotNamespace>/</robotNamespace>
      <robotParam>robot_description</robotParam>
      <robotSimType>wheellegged_gazebo/WheelleggedHWSim</robotSimType>
    </plugin>
  </gazebo>
  <gazebo>
    <plugin filename="libgazebo_ros_p3d.so" name="p3d_base_controller">
      <alwaysOn>true</alwaysOn>
      <updateRate>1000.0</updateRate>
      <bodyName>base</bodyName>
      <topicName>Odometry</topicName>
      <gaussianNoise>0</gaussianNoise>
      <frameName>world</frameName>
      <xyzOffsets>0 0 0</xyzOffsets>
      <rpyOffsets>0 0 0</rpyOffsets>
    </plugin>
  </gazebo>
  <gazebo reference="base_link">
    <maxVel>100.</maxVel>
    <kp>10000.</kp>
    <kd>0.</kd>
  </gazebo>
  <gazebo reference="stick_link">
    <mu1>0.2</mu1>
    <mu2>0.2</mu2>
    <material>Gazebo/White</material>
  </gazebo>
  <!-- LF leg -->
  <gazebo reference="LF_hip">
    <mu1>0.2</mu1>
    <mu2>0.2</mu2>
    <material>Gazebo/DarkGrey</material>
  </gazebo>
  <gazebo reference="LF_thigh">
    <mu1>0.2</mu1>
    <mu2>0.2</mu2>
    <self_collide>0</self_collide>
    <material>Gazebo/DarkGrey</material>
    <kp value="1000000.0"/>
    <kd value="1.0"/>
  </gazebo>
  <gazebo reference="LF_calf">
    <mu1>0.2</mu1>
    <mu2>0.2</mu2>
    <self_collide>1</self_collide>
  </gazebo>
  <gazebo reference="LF_wheel">
    <mu1>0.6</mu1>
    <mu2>0.6</mu2>
    <self_collide>1</self_collide>
    <material>Gazebo/DarkGrey</material>
    <kp value="1000000.0"/>
    <kd value="1.0"/>
  </gazebo>
  <gazebo reference="LF_foot">
    <mu1>0.6</mu1>
    <mu2>0.6</mu2>
    <self_collide>0</self_collide>
    <material>Gazebo/White</material>
    <kp value="1000000.0"/>
    <kd value="1.0"/>
  </gazebo>
  <!-- RF leg -->
  <gazebo reference="RF_hip">
    <mu1>0.2</mu1>
    <mu2>0.2</mu2>
    <material>Gazebo/DarkGrey</material>
  </gazebo>
  <gazebo reference="RF_thigh">
    <mu1>0.2</mu1>
    <mu2>0.2</mu2>
    <self_collide>0</self_collide>
    <material>Gazebo/DarkGrey</material>
    <kp value="1000000.0"/>
    <kd value="1.0"/>
  </gazebo>
  <gazebo reference="RF_calf">
    <mu1>0.2</mu1>
    <mu2>0.2</mu2>
    <self_collide>1</self_collide>
  </gazebo>
  <gazebo reference="RF_wheel">
    <mu1>0.6</mu1>
    <mu2>0.6</mu2>
    <self_collide>1</self_collide>
    <material>Gazebo/DarkGrey</material>
    <kp value="1000000.0"/>
    <kd value="1.0"/>
  </gazebo>
  <gazebo reference="RF_foot">
    <mu1>0.6</mu1>
    <mu2>0.6</mu2>
    <self_collide>0</self_collide>
    <material>Gazebo/White</material>
    <kp value="1000000.0"/>
    <kd value="1.0"/>
  </gazebo>
  <!-- LH leg -->
  <gazebo reference="LH_hip">
    <mu1>0.2</mu1>
    <mu2>0.2</mu2>
    <material>Gazebo/DarkGrey</material>
  </gazebo>
  <gazebo reference="LH_thigh">
    <mu1>0.2</mu1>
    <mu2>0.2</mu2>
    <self_collide>0</self_collide>
    <material>Gazebo/DarkGrey</material>
    <kp value="1000000.0"/>
    <kd value="1.0"/>
  </gazebo>
  <gazebo reference="LH_calf">
    <mu1>0.2</mu1>
    <mu2>0.2</mu2>
    <self_collide>1</self_collide>
  </gazebo>
  <gazebo reference="LH_wheel">
    <mu1>0.6</mu1>
    <mu2>0.6</mu2>
    <self_collide>1</self_collide>
    <material>Gazebo/DarkGrey</material>
    <kp value="1000000.0"/>
    <kd value="1.0"/>
  </gazebo>
  <gazebo reference="LH_foot">
    <mu1>0.6</mu1>
    <mu2>0.6</mu2>
    <self_collide>0</self_collide>
    <material>Gazebo/White</material>
    <kp value="1000000.0"/>
    <kd value="1.0"/>
  </gazebo>
  <!-- RH leg -->
  <gazebo reference="RH_hip">
    <mu1>0.2</mu1>
    <mu2>0.2</mu2>
    <material>Gazebo/DarkGrey</material>
  </gazebo>
  <gazebo reference="RH_thigh">
    <mu1>0.2</mu1>
    <mu2>0.2</mu2>
    <self_collide>0</self_collide>
    <material>Gazebo/DarkGrey</material>
    <kp value="1000000.0"/>
    <kd value="1.0"/>
  </gazebo>
  <gazebo reference="RH_calf">
    <mu1>0.2</mu1>
    <mu2>0.2</mu2>
    <self_collide>1</self_collide>
  </gazebo>
  <gazebo reference="RH_wheel">
    <mu1>0.6</mu1>
    <mu2>0.6</mu2>
    <self_collide>1</self_collide>
    <material>Gazebo/DarkGrey</material>
    <kp value="1000000.0"/>
    <kd value="1.0"/>
  </gazebo>
  <gazebo reference="RH_foot">
    <mu1>0.6</mu1>
    <mu2>0.6</mu2>
    <self_collide>0</self_collide>
    <material>Gazebo/White</material>
    <kp value="1000000.0"/>
    <kd value="1.0"/>
  </gazebo>
  <link name="base">
    <visual>
      <origin rpy="0 0 0" xyz="0 0 0"/>
      <geometry>
        <mesh filename="package://robot_description/wheellegged/WL_P311B/meshes/base_link.STL" scale="1 1 1"/>
      </geometry>
      <material name="orange">
        <color rgba="0.752941176470588 0.752941176470588 0.752941176470588 1"/>
      </material>
    </visual>
    <collision>
      <origin rpy="0 0 0" xyz="0 0 0.02975"/>
      <geometry>
        <box size="0.53 0.24 0.14"/>
      </geometry>
    </collision>
    <inertial>
      <origin rpy="0 0 0" xyz="0.003396 -0.000145 0.043418"/>
      <mass value="13.802"/>
      <inertia ixx="0.099620756" ixy="0.000709689" ixz="-0.001385087" iyy="0.515768352" iyz="-5.3627e-05" izz="0.555803877"/>
    </inertial>
  </link>
  <!-- Imu is fixed to the base link -->
  <joint name="limx_imu_joint" type="fixed">
    <origin rpy="0. 0. 0." xyz="0. 0. 0."/>
    <parent link="base"/>
    <child link="limx_imu"/>
  </joint>
  <!-- Imu link -->
  <link name="limx_imu">
    <inertial>
      <mass value="0.01"/>
      <origin rpy="0 0 0" xyz="0 0 0"/>
      <inertia ixx="0.000001" ixy="0" ixz="0" iyy="0.000001" iyz="0" izz="0.000001"/>
    </inertial>
    <visual>
      <origin rpy="0 0 0" xyz="0 0 0"/>
      <geometry>
        <box size="0.015 0.015 0.004"/>
      </geometry>
    </visual>
    <material name="orange">
      <color rgba="255 108 10 255"/>
    </material>
  </link>
  <gazebo reference="limx_imu">
    <material>Gazebo/Orange</material>
  </gazebo>
  <gazebo reference="limx_imu_joint">
    <disableFixedJointLumping>true</disableFixedJointLumping>
  </gazebo>

   <joint name="support_joint1" type="fixed">
       <origin rpy="0. 0. 0." xyz="0.25 0.1 -0.12"/>
       <parent link="base"/>
       <child link="support1"/>
   </joint>
   <!-- &lt;!&ndash; support link &ndash;&gt; -->
   <link name="support1">
       <collision>
           <origin rpy="0 0 0" xyz="0 0 0"/>
           <geometry>
               <box size="0.015 0.015 0.004"/>
           </geometry>
       </collision>
   </link>
   <joint name="support_joint2" type="fixed">
       <origin rpy="0. 0. 0." xyz="-0.25 0.1 -0.12"/>
       <parent link="base"/>
       <child link="support2"/>
   </joint>
   <!-- &lt;!&ndash; support link &ndash;&gt; -->
   <link name="support2">
       <collision>
           <origin rpy="0 0 0" xyz="0 0 0"/>
           <geometry>
               <box size="0.015 0.015 0.004"/>
           </geometry>
       </collision>
   </link>
   <joint name="support_joint3" type="fixed">
       <origin rpy="0. 0. 0." xyz="0.25 -0.1 -0.12"/>
       <parent link="base"/>
       <child link="support3"/>
   </joint>
   <!-- &lt;!&ndash; support link &ndash;&gt; -->
   <link name="support3">
       <collision>
           <origin rpy="0 0 0" xyz="0 0 0"/>
           <geometry>
               <box size="0.015 0.015 0.004"/>
           </geometry>
       </collision>
   </link>
   <joint name="support_joint4" type="fixed">
       <origin rpy="0. 0. 0." xyz="-0.25 -0.1 -0.12"/>
       <parent link="base"/>
       <child link="support4"/>
   </joint>
<!--    &lt;!&ndash; support link &ndash;&gt;-->
   <link name="support4">
       <collision>
           <origin rpy="0 0 0" xyz="0 0 0"/>
           <geometry>
               <box size="0.015 0.015 0.004"/>
           </geometry>
       </collision>
   </link>

  <joint name="LF_HAA" type="revolute">
    <origin rpy="0 0 0" xyz="0.261 0.0625 0.04475"/>
    <parent link="base"/>
    <child link="LF_hip"/>
    <axis xyz="1 0 0"/>
    <dynamics damping="0.05" friction="0.01"/>
    <limit effort="60" lower="-0.87" upper="0.87" velocity="20"/>
  </joint>
  <link name="LF_hip">
    <visual>
      <origin rpy="0 0 0" xyz="0 0 0"/>
      <geometry>
        <mesh filename="package://robot_description/wheellegged/WL_P311B/meshes/LF_hip.STL" scale="1 1 1"/>
      </geometry>
      <material name="orange"/>
      <color rgba="0.8902 0.8902 0.91373 1"/>
    </visual>
    <inertial>
      <origin rpy="0 0 0" xyz="0.059344 0.00265 -6e-05"/>
      <mass value="1.009"/>
      <inertia ixx="0.000932791" ixy="-2.848e-06" ixz="2.01e-07" iyy="0.001815897" iyz="9.4e-08" izz="0.00140841"/>
    </inertial>
  </link>
  <joint name="LF_HFE" type="revolute">
    <origin rpy="0 0 0" xyz="0.0703 0.02735 0"/>
    <parent link="LF_hip"/>
    <child link="LF_thigh"/>
    <axis xyz="0 1 0"/>
    <dynamics damping="0.05" friction="0.01"/>
    <limit effort="60" lower="-2.27" upper="1.22" velocity="20"/>
  </joint>
  <link name="LF_thigh">
    <visual>
      <origin rpy="0 0 0" xyz="0 0 0"/>
      <geometry>
        <mesh filename="package://robot_description/wheellegged/WL_P311B/meshes/LF_thigh.STL" scale="1 1 1"/>
      </geometry>
      <material name="orange"/>
      <color rgba="0.8902 0.8902 0.91373 1"/>
    </visual>
    <inertial>
      <origin rpy="0 0 0" xyz="-0.06501 0.055862 0.004642"/>
      <mass value="2.046"/>
      <inertia ixx="0.003056637" ixy="0.003097718" ixz="0.001189321" iyy="0.023830538" iyz="-0.000266054" izz="0.024091346"/>
    </inertial>
  </link>
  <joint name="LF_KFE" type="revolute">
    <origin rpy="0 0 0" xyz="-0.3 0.0778 0"/>
    <parent link="LF_thigh"/>
    <child link="LF_calf"/>
    <axis xyz="0 1 0"/>
    <dynamics damping="0.05" friction="0.01"/>
    <limit effort="60" lower="0.0" upper="2.39" velocity="20"/>
  </joint>
  <link name="LF_calf">
    <visual>
      <origin rpy="0 0 0" xyz="0 0 0"/>
      <geometry>
        <mesh filename="package://robot_description/wheellegged/WL_P311B/meshes/LF_calf.STL" scale="1 1 1"/>
      </geometry>
      <material name="orange"/>
      <color rgba="0.20392 0.20392 0.20392 1"/>
    </visual>
    <collision>
      <origin rpy="0 0.41887902047863906 0" xyz="0.1 0 -0.036"/>
      <geometry>
        <box size="0.3 0.0258 0.02"/>
      </geometry>
    </collision>
    <inertial>
      <origin rpy="0 0 0" xyz="0.216955 0.016325 -0.095385"/>
      <mass value="1.017"/>
      <inertia ixx="0.002710199" ixy="-0.000951849" ixz="0.00428671" iyy="0.012382431" iyz="0.000442771" izz="0.01025361"/>
    </inertial>
  </link>
  <joint name="LF_WHL" type="revolute">
    <origin rpy="0 -0.3 0" xyz="0.27393 0.0467 -0.12214"/>
    <parent link="LF_calf"/>
    <child link="LF_wheel"/>
    <axis xyz="0 1 0"/>
    <limit effort="20" lower="-1000" upper="1000" velocity="20"/>
    <dynamics friction="0.1"/>
  </joint>
  <link name="LF_wheel">
    <visual>
      <origin rpy="0 0 0" xyz="0 0 0"/>
      <geometry>
        <mesh filename="package://robot_description/wheellegged/WL_P311B/meshes/LF_wheel.STL" scale="1 1 1"/>
      </geometry>
      <material name="orange"/>
      <color rgba="0.69804 0.69804 0.69804 1"/>
    </visual>
    <collision>
      <origin rpy="1.5707963267948966 0 0" xyz="0 0 0"/>
      <geometry>
        <cylinder length="0.017" radius="0.127"/>
      </geometry>
    </collision>
    <inertial>
      <origin rpy="0 0 0" xyz="0.000128 0.000934 8.3e-05"/>
      <mass value="0.857"/>
      <inertia ixx="0.003668469" ixy="5.3e-08" ixz="-4.28e-07" iyy="0.007037425" iyz="-3.8e-08" izz="0.00367221"/>
    </inertial>
  </link>
  <joint name="LF_foot_fixed" type="fixed">
    <parent link="LF_wheel"/>
    <child link="LF_foot"/>
    <origin rpy="0 0 0" xyz="0 0 -0.127"/>
  </joint>
  <link name="LF_foot">
    <visual>
      <origin rpy="0 0 0" xyz="0 0 0"/>
      <geometry>
        <sphere radius="0.001"/>
      </geometry>
    </visual>
  </link>
  <gazebo reference="LF_foot_fixed">
    <disableFixedJointLumping>true</disableFixedJointLumping>
  </gazebo>
  <transmission name="LF_HAA_tran">
    <type>transmission_interface/SimpleTransmission</type>
    <joint name="LF_HAA">
      <hardwareInterface>hardware_interface/EffortJointInterface</hardwareInterface>
    </joint>
    <actuator name="LF_HAA_motor">
      <hardwareInterface>hardware_interface/EffortJointInterface</hardwareInterface>
      <mechanicalReduction>1</mechanicalReduction>
    </actuator>
  </transmission>
  <transmission name="LF_HFE_tran">
    <type>transmission_interface/SimpleTransmission</type>
    <joint name="LF_HFE">
      <hardwareInterface>hardware_interface/EffortJointInterface</hardwareInterface>
    </joint>
    <actuator name="LF_HFE_motor">
      <hardwareInterface>hardware_interface/EffortJointInterface</hardwareInterface>
      <mechanicalReduction>1</mechanicalReduction>
    </actuator>
  </transmission>
  <transmission name="LF_KFE_tran">
    <type>transmission_interface/SimpleTransmission</type>
    <joint name="LF_KFE">
      <hardwareInterface>hardware_interface/EffortJointInterface</hardwareInterface>
    </joint>
    <actuator name="LF_KFE_motor">
      <hardwareInterface>hardware_interface/EffortJointInterface</hardwareInterface>
      <mechanicalReduction>1</mechanicalReduction>
    </actuator>
  </transmission>
  <transmission name="LF_WHL_tran">
    <type>transmission_interface/SimpleTransmission</type>
    <joint name="LF_WHL">
      <hardwareInterface>hardware_interface/EffortJointInterface</hardwareInterface>
    </joint>
    <actuator name="LF_WHL_motor">
      <hardwareInterface>hardware_interface/EffortJointInterface</hardwareInterface>
      <mechanicalReduction>1</mechanicalReduction>
    </actuator>
  </transmission>
  <joint name="RF_HAA" type="revolute">
    <origin rpy="0 0 0" xyz="0.261 -0.0625 0.04475"/>
    <parent link="base"/>
    <child link="RF_hip"/>
    <axis xyz="1 0 0"/>
    <dynamics damping="0.05" friction="0.01"/>
    <limit effort="60" lower="-0.87" upper="0.87" velocity="20"/>
  </joint>
  <link name="RF_hip">
    <visual>
      <origin rpy="0 0 0" xyz="0 0 0"/>
      <geometry>
        <mesh filename="package://robot_description/wheellegged/WL_P311B/meshes/RF_hip.STL" scale="1 1 1"/>
      </geometry>
      <material name="orange"/>
      <color rgba="0.8902 0.8902 0.91373 1"/>
    </visual>
    <inertial>
      <origin rpy="0 0 0" xyz="0.059344 -0.00265 -6e-05"/>
      <mass value="1.009"/>
      <inertia ixx="0.000932791" ixy="2.848e-06" ixz="2.01e-07" iyy="0.001815897" iyz="-9.4e-08" izz="0.00140841"/>
    </inertial>
  </link>
  <joint name="RF_HFE" type="revolute">
    <origin rpy="0 0 0" xyz="0.0703 -0.02735 0"/>
    <parent link="RF_hip"/>
    <child link="RF_thigh"/>
    <axis xyz="0 1 0"/>
    <dynamics damping="0.05" friction="0.01"/>
    <limit effort="60" lower="-2.27" upper="1.22" velocity="20"/>
  </joint>
  <link name="RF_thigh">
    <visual>
      <origin rpy="0 0 0" xyz="0 0 0"/>
      <geometry>
        <mesh filename="package://robot_description/wheellegged/WL_P311B/meshes/RF_thigh.STL" scale="1 1 1"/>
      </geometry>
      <material name="orange"/>
      <color rgba="0.8902 0.8902 0.91373 1"/>
    </visual>
    <inertial>
      <origin rpy="0 0 0" xyz="-0.06501 -0.055862 0.004642"/>
      <mass value="2.046"/>
      <inertia ixx="0.003056637" ixy="-0.003097718" ixz="0.001189321" iyy="0.023830538" iyz="0.000266054" izz="0.024091346"/>
    </inertial>
  </link>
  <joint name="RF_KFE" type="revolute">
    <origin rpy="0 0 0" xyz="-0.3 -0.0778 0"/>
    <parent link="RF_thigh"/>
    <child link="RF_calf"/>
    <axis xyz="0 1 0"/>
    <dynamics damping="0.05" friction="0.01"/>
    <limit effort="60" lower="0.0" upper="2.39" velocity="20"/>
  </joint>
  <link name="RF_calf">
    <visual>
      <origin rpy="0 0 0" xyz="0 0 0"/>
      <geometry>
        <mesh filename="package://robot_description/wheellegged/WL_P311B/meshes/RF_calf.STL" scale="1 1 1"/>
      </geometry>
      <material name="orange"/>
      <color rgba="0.20392 0.20392 0.20392 1"/>
    </visual>
    <collision>
      <origin rpy="0 0.41887902047863906 0" xyz="0.1 0 -0.036"/>
      <geometry>
        <box size="0.3 0.0258 0.02"/>
      </geometry>
    </collision>
    <inertial>
      <origin rpy="0 0 0" xyz="0.216955 -0.016325 -0.095385"/>
      <mass value="1.017"/>
      <inertia ixx="0.002710199" ixy="0.000951849" ixz="0.00428671" iyy="0.012382431" iyz="-0.000442771" izz="0.01025361"/>
    </inertial>
  </link>
  <joint name="RF_WHL" type="revolute">
    <origin rpy="0 -0.3 0" xyz="0.27393 -0.0467 -0.12214"/>
    <parent link="RF_calf"/>
    <child link="RF_wheel"/>
    <axis xyz="0 1 0"/>
    <limit effort="20" lower="-1000" upper="1000" velocity="20"/>
    <dynamics friction="0.1"/>
  </joint>
  <link name="RF_wheel">
    <visual>
      <origin rpy="0 0 0" xyz="0 0 0"/>
      <geometry>
        <mesh filename="package://robot_description/wheellegged/WL_P311B/meshes/RF_wheel.STL" scale="1 1 1"/>
      </geometry>
      <material name="orange"/>
      <color rgba="0.69804 0.69804 0.69804 1"/>
    </visual>
    <collision>
      <origin rpy="1.5707963267948966 0 0" xyz="0 0 0"/>
      <geometry>
        <cylinder length="0.017" radius="0.127"/>
      </geometry>
    </collision>
    <inertial>
      <origin rpy="0 0 0" xyz="0.000128 -0.000934 8.3e-05"/>
      <mass value="0.857"/>
      <inertia ixx="0.003668469" ixy="-5.3e-08" ixz="-4.28e-07" iyy="0.007037425" iyz="3.8e-08" izz="0.00367221"/>
    </inertial>
  </link>
  <joint name="RF_foot_fixed" type="fixed">
    <parent link="RF_wheel"/>
    <child link="RF_foot"/>
    <origin rpy="0 0 0" xyz="0 0 -0.127"/>
  </joint>
  <link name="RF_foot">
    <visual>
      <origin rpy="0 0 0" xyz="0 0 0"/>
      <geometry>
        <sphere radius="0.001"/>
      </geometry>
    </visual>
  </link>
  <gazebo reference="RF_foot_fixed">
    <disableFixedJointLumping>true</disableFixedJointLumping>
  </gazebo>
  <transmission name="RF_HAA_tran">
    <type>transmission_interface/SimpleTransmission</type>
    <joint name="RF_HAA">
      <hardwareInterface>hardware_interface/EffortJointInterface</hardwareInterface>
    </joint>
    <actuator name="RF_HAA_motor">
      <hardwareInterface>hardware_interface/EffortJointInterface</hardwareInterface>
      <mechanicalReduction>1</mechanicalReduction>
    </actuator>
  </transmission>
  <transmission name="RF_HFE_tran">
    <type>transmission_interface/SimpleTransmission</type>
    <joint name="RF_HFE">
      <hardwareInterface>hardware_interface/EffortJointInterface</hardwareInterface>
    </joint>
    <actuator name="RF_HFE_motor">
      <hardwareInterface>hardware_interface/EffortJointInterface</hardwareInterface>
      <mechanicalReduction>1</mechanicalReduction>
    </actuator>
  </transmission>
  <transmission name="RF_KFE_tran">
    <type>transmission_interface/SimpleTransmission</type>
    <joint name="RF_KFE">
      <hardwareInterface>hardware_interface/EffortJointInterface</hardwareInterface>
    </joint>
    <actuator name="RF_KFE_motor">
      <hardwareInterface>hardware_interface/EffortJointInterface</hardwareInterface>
      <mechanicalReduction>1</mechanicalReduction>
    </actuator>
  </transmission>
  <transmission name="RF_WHL_tran">
    <type>transmission_interface/SimpleTransmission</type>
    <joint name="RF_WHL">
      <hardwareInterface>hardware_interface/EffortJointInterface</hardwareInterface>
    </joint>
    <actuator name="RF_WHL_motor">
      <hardwareInterface>hardware_interface/EffortJointInterface</hardwareInterface>
      <mechanicalReduction>1</mechanicalReduction>
    </actuator>
  </transmission>
  <joint name="LH_HAA" type="revolute">
    <origin rpy="0 0 0" xyz="-0.261 0.0625 0.04475"/>
    <parent link="base"/>
    <child link="LH_hip"/>
    <axis xyz="1 0 0"/>
    <dynamics damping="0.05" friction="0.01"/>
    <limit effort="60" lower="-0.87" upper="0.87" velocity="20"/>
  </joint>
  <link name="LH_hip">
    <visual>
      <origin rpy="0 0 0" xyz="0 0 0"/>
      <geometry>
        <mesh filename="package://robot_description/wheellegged/WL_P311B/meshes/LH_hip.STL" scale="1 1 1"/>
      </geometry>
      <material name="orange"/>
      <color rgba="0.8902 0.8902 0.91373 1"/>
    </visual>
    <inertial>
      <origin rpy="0 0 0" xyz="-0.059344 0.00265 -6e-05"/>
      <mass value="1.009"/>
      <inertia ixx="0.000932791" ixy="2.848e-06" ixz="-2.01e-07" iyy="0.001815897" iyz="9.4e-08" izz="0.00140841"/>
    </inertial>
  </link>
  <joint name="LH_HFE" type="revolute">
    <origin rpy="0 0 0" xyz="-0.0703 0.02735 0"/>
    <parent link="LH_hip"/>
    <child link="LH_thigh"/>
    <axis xyz="0 1 0"/>
    <dynamics damping="0.05" friction="0.01"/>
    <limit effort="60" lower="-2.27" upper="1.22" velocity="20"/>
  </joint>
  <link name="LH_thigh">
    <visual>
      <origin rpy="0 0 0" xyz="0 0 0"/>
      <geometry>
        <mesh filename="package://robot_description/wheellegged/WL_P311B/meshes/LH_thigh.STL" scale="1 1 1"/>
      </geometry>
      <material name="orange"/>
      <color rgba="0.8902 0.8902 0.91373 1"/>
    </visual>
    <inertial>
      <origin rpy="0 0 0" xyz="-0.06501 0.055862 0.004642"/>
      <mass value="2.046"/>
      <inertia ixx="0.003056637" ixy="0.003097718" ixz="0.001189321" iyy="0.023830538" iyz="-0.000266054" izz="0.024091346"/>
    </inertial>
  </link>
  <joint name="LH_KFE" type="revolute">
    <origin rpy="0 0 0" xyz="-0.3 0.0778 0"/>
    <parent link="LH_thigh"/>
    <child link="LH_calf"/>
    <axis xyz="0 1 0"/>
    <dynamics damping="0.05" friction="0.01"/>
    <limit effort="60" lower="0.0" upper="2.39" velocity="20"/>
  </joint>
  <link name="LH_calf">
    <visual>
      <origin rpy="0 0 0" xyz="0 0 0"/>
      <geometry>
        <mesh filename="package://robot_description/wheellegged/WL_P311B/meshes/LH_calf.STL" scale="1 1 1"/>
      </geometry>
      <material name="orange"/>
      <color rgba="0.20392 0.20392 0.20392 1"/>
    </visual>
    <collision>
      <origin rpy="0 0.41887902047863906 0" xyz="0.1 0 -0.036"/>
      <geometry>
        <box size="0.3 0.0258 0.02"/>
      </geometry>
    </collision>
    <inertial>
      <origin rpy="0 0 0" xyz="0.216955 0.016325 -0.095385"/>
      <mass value="1.017"/>
      <inertia ixx="0.002710199" ixy="-0.000951849" ixz="0.00428671" iyy="0.012382431" iyz="0.000442771" izz="0.01025361"/>
    </inertial>
  </link>
  <joint name="LH_WHL" type="revolute">
    <origin rpy="0 -0.3 0" xyz="0.27393 0.0467 -0.12214"/>
    <parent link="LH_calf"/>
    <child link="LH_wheel"/>
    <axis xyz="0 1 0"/>
    <limit effort="20" lower="-1000" upper="1000" velocity="20"/>
    <dynamics friction="0.1"/>
  </joint>
  <link name="LH_wheel">
    <visual>
      <origin rpy="0 0 0" xyz="0 0 0"/>
      <geometry>
        <mesh filename="package://robot_description/wheellegged/WL_P311B/meshes/LH_wheel.STL" scale="1 1 1"/>
      </geometry>
      <material name="orange"/>
      <color rgba="0.69804 0.69804 0.69804 1"/>
    </visual>
    <collision>
      <origin rpy="1.5707963267948966 0 0" xyz="0 0 0"/>
      <geometry>
        <cylinder length="0.017" radius="0.127"/>
      </geometry>
    </collision>
    <inertial>
      <origin rpy="0 0 0" xyz="0.000128 0.000934 8.3e-05"/>
      <mass value="0.857"/>
      <inertia ixx="0.003668469" ixy="5.3e-08" ixz="-4.28e-07" iyy="0.007037425" iyz="-3.8e-08" izz="0.00367221"/>
    </inertial>
  </link>
  <joint name="LH_foot_fixed" type="fixed">
    <parent link="LH_wheel"/>
    <child link="LH_foot"/>
    <origin rpy="0 0 0" xyz="0 0 -0.127"/>
  </joint>
  <link name="LH_foot">
    <visual>
      <origin rpy="0 0 0" xyz="0 0 0"/>
      <geometry>
        <sphere radius="0.001"/>
      </geometry>
    </visual>
  </link>
  <gazebo reference="LH_foot_fixed">
    <disableFixedJointLumping>true</disableFixedJointLumping>
  </gazebo>
  <transmission name="LH_HAA_tran">
    <type>transmission_interface/SimpleTransmission</type>
    <joint name="LH_HAA">
      <hardwareInterface>hardware_interface/EffortJointInterface</hardwareInterface>
    </joint>
    <actuator name="LH_HAA_motor">
      <hardwareInterface>hardware_interface/EffortJointInterface</hardwareInterface>
      <mechanicalReduction>1</mechanicalReduction>
    </actuator>
  </transmission>
  <transmission name="LH_HFE_tran">
    <type>transmission_interface/SimpleTransmission</type>
    <joint name="LH_HFE">
      <hardwareInterface>hardware_interface/EffortJointInterface</hardwareInterface>
    </joint>
    <actuator name="LH_HFE_motor">
      <hardwareInterface>hardware_interface/EffortJointInterface</hardwareInterface>
      <mechanicalReduction>1</mechanicalReduction>
    </actuator>
  </transmission>
  <transmission name="LH_KFE_tran">
    <type>transmission_interface/SimpleTransmission</type>
    <joint name="LH_KFE">
      <hardwareInterface>hardware_interface/EffortJointInterface</hardwareInterface>
    </joint>
    <actuator name="LH_KFE_motor">
      <hardwareInterface>hardware_interface/EffortJointInterface</hardwareInterface>
      <mechanicalReduction>1</mechanicalReduction>
    </actuator>
  </transmission>
  <transmission name="LH_WHL_tran">
    <type>transmission_interface/SimpleTransmission</type>
    <joint name="LH_WHL">
      <hardwareInterface>hardware_interface/EffortJointInterface</hardwareInterface>
    </joint>
    <actuator name="LH_WHL_motor">
      <hardwareInterface>hardware_interface/EffortJointInterface</hardwareInterface>
      <mechanicalReduction>1</mechanicalReduction>
    </actuator>
  </transmission>
  <joint name="RH_HAA" type="revolute">
    <origin rpy="0 0 0" xyz="-0.261 -0.0625 0.04475"/>
    <parent link="base"/>
    <child link="RH_hip"/>
    <axis xyz="1 0 0"/>
    <dynamics damping="0.05" friction="0.01"/>
    <limit effort="60" lower="-0.87" upper="0.87" velocity="20"/>
  </joint>
  <link name="RH_hip">
    <visual>
      <origin rpy="0 0 0" xyz="0 0 0"/>
      <geometry>
        <mesh filename="package://robot_description/wheellegged/WL_P311B/meshes/RH_hip.STL" scale="1 1 1"/>
      </geometry>
      <material name="orange"/>
      <color rgba="0.8902 0.8902 0.91373 1"/>
    </visual>
    <inertial>
      <origin rpy="0 0 0" xyz="-0.059344 -0.00265 -6e-05"/>
      <mass value="1.009"/>
      <inertia ixx="0.000932791" ixy="-2.848e-06" ixz="-2.01e-07" iyy="0.001815897" iyz="-9.4e-08" izz="0.00140841"/>
    </inertial>
  </link>
  <joint name="RH_HFE" type="revolute">
    <origin rpy="0 0 0" xyz="-0.0703 -0.02735 0"/>
    <parent link="RH_hip"/>
    <child link="RH_thigh"/>
    <axis xyz="0 1 0"/>
    <dynamics damping="0.05" friction="0.01"/>
    <limit effort="60" lower="-2.27" upper="1.22" velocity="20"/>
  </joint>
  <link name="RH_thigh">
    <visual>
      <origin rpy="0 0 0" xyz="0 0 0"/>
      <geometry>
        <mesh filename="package://robot_description/wheellegged/WL_P311B/meshes/RH_thigh.STL" scale="1 1 1"/>
      </geometry>
      <material name="orange"/>
      <color rgba="0.8902 0.8902 0.91373 1"/>
    </visual>
    <inertial>
      <origin rpy="0 0 0" xyz="-0.06501 -0.055862 0.004642"/>
      <mass value="2.046"/>
      <inertia ixx="0.003056637" ixy="-0.003097718" ixz="0.001189321" iyy="0.023830538" iyz="0.000266054" izz="0.024091346"/>
    </inertial>
  </link>
  <joint name="RH_KFE" type="revolute">
    <origin rpy="0 0 0" xyz="-0.3 -0.0778 0"/>
    <parent link="RH_thigh"/>
    <child link="RH_calf"/>
    <axis xyz="0 1 0"/>
    <dynamics damping="0.05" friction="0.01"/>
    <limit effort="60" lower="0.0" upper="2.39" velocity="20"/>
  </joint>
  <link name="RH_calf">
    <visual>
      <origin rpy="0 0 0" xyz="0 0 0"/>
      <geometry>
        <mesh filename="package://robot_description/wheellegged/WL_P311B/meshes/RH_calf.STL" scale="1 1 1"/>
      </geometry>
      <material name="orange"/>
      <color rgba="0.20392 0.20392 0.20392 1"/>
    </visual>
    <collision>
      <origin rpy="0 0.41887902047863906 0" xyz="0.1 0 -0.036"/>
      <geometry>
        <box size="0.3 0.0258 0.02"/>
      </geometry>
    </collision>
    <inertial>
      <origin rpy="0 0 0" xyz="0.216955 -0.016325 -0.095385"/>
      <mass value="1.017"/>
      <inertia ixx="0.002710199" ixy="0.000951849" ixz="0.00428671" iyy="0.012382431" iyz="-0.000442771" izz="0.01025361"/>
    </inertial>
  </link>
  <joint name="RH_WHL" type="revolute">
    <origin rpy="0 -0.3 0" xyz="0.27393 -0.0467 -0.12214"/>
    <parent link="RH_calf"/>
    <child link="RH_wheel"/>
    <axis xyz="0 1 0"/>
    <limit effort="20" lower="-1000" upper="1000" velocity="20"/>
    <dynamics friction="0.1"/>
  </joint>
  <link name="RH_wheel">
    <visual>
      <origin rpy="0 0 0" xyz="0 0 0"/>
      <geometry>
        <mesh filename="package://robot_description/wheellegged/WL_P311B/meshes/RH_wheel.STL" scale="1 1 1"/>
      </geometry>
      <material name="orange"/>
      <color rgba="0.69804 0.69804 0.69804 1"/>
    </visual>
    <collision>
      <origin rpy="1.5707963267948966 0 0" xyz="0 0 0"/>
      <geometry>
        <cylinder length="0.017" radius="0.127"/>
      </geometry>
    </collision>
    <inertial>
      <origin rpy="0 0 0" xyz="0.000128 -0.000934 8.3e-05"/>
      <mass value="0.857"/>
      <inertia ixx="0.003668469" ixy="-5.3e-08" ixz="-4.28e-07" iyy="0.007037425" iyz="3.8e-08" izz="0.00367221"/>
    </inertial>
  </link>
  <joint name="RH_foot_fixed" type="fixed">
    <parent link="RH_wheel"/>
    <child link="RH_foot"/>
    <origin rpy="0 0 0" xyz="0 0 -0.127"/>
  </joint>
  <link name="RH_foot">
    <visual>
      <origin rpy="0 0 0" xyz="0 0 0"/>
      <geometry>
        <sphere radius="0.001"/>
      </geometry>
    </visual>
  </link>
  <gazebo reference="RH_foot_fixed">
    <disableFixedJointLumping>true</disableFixedJointLumping>
  </gazebo>
  <transmission name="RH_HAA_tran">
    <type>transmission_interface/SimpleTransmission</type>
    <joint name="RH_HAA">
      <hardwareInterface>hardware_interface/EffortJointInterface</hardwareInterface>
    </joint>
    <actuator name="RH_HAA_motor">
      <hardwareInterface>hardware_interface/EffortJointInterface</hardwareInterface>
      <mechanicalReduction>1</mechanicalReduction>
    </actuator>
  </transmission>
  <transmission name="RH_HFE_tran">
    <type>transmission_interface/SimpleTransmission</type>
    <joint name="RH_HFE">
      <hardwareInterface>hardware_interface/EffortJointInterface</hardwareInterface>
    </joint>
    <actuator name="RH_HFE_motor">
      <hardwareInterface>hardware_interface/EffortJointInterface</hardwareInterface>
      <mechanicalReduction>1</mechanicalReduction>
    </actuator>
  </transmission>
  <transmission name="RH_KFE_tran">
    <type>transmission_interface/SimpleTransmission</type>
    <joint name="RH_KFE">
      <hardwareInterface>hardware_interface/EffortJointInterface</hardwareInterface>
    </joint>
    <actuator name="RH_KFE_motor">
      <hardwareInterface>hardware_interface/EffortJointInterface</hardwareInterface>
      <mechanicalReduction>1</mechanicalReduction>
    </actuator>
  </transmission>
  <transmission name="RH_WHL_tran">
    <type>transmission_interface/SimpleTransmission</type>
    <joint name="RH_WHL">
      <hardwareInterface>hardware_interface/EffortJointInterface</hardwareInterface>
    </joint>
    <actuator name="RH_WHL_motor">
      <hardwareInterface>hardware_interface/EffortJointInterface</hardwareInterface>
      <mechanicalReduction>1</mechanicalReduction>
    </actuator>
  </transmission>
    <!-- ****************************************** D435 frontL Camera ******************************************************** -->
    <joint name="d435FL_joint" type="fixed">
        <origin rpy="1.35821 0.363706 -0.54538" xyz="0.487 0.04 0.063"/>
        <parent link="base"/>
        <child link="d435FL_link"/>
    </joint>
    <link name="d435FL_link">
        <visual>
            <origin rpy="1.5707963267948966 0 1.5707963267948966" xyz="0.0149 -0.0175 0"/>
            <geometry>
                <mesh filename="package://robot_description/wheellegged/WL_P311B/meshes/realsense_d435.stl"/>
            </geometry>
        </visual>
        <collision>
            <origin rpy="0 0 0" xyz="0 -0.0175 0"/>
            <geometry>
                <box size="0.02505 0.09 0.025"/>
            </geometry>
        </collision>
    </link>
    <joint name="d435FL_depth_joint" type="fixed">
        <origin rpy="0 0 0" xyz="0 0 0"/>
        <parent link="d435FL_link"/>
        <child link="d435FL_depth_frame"/>
    </joint>
    <link name="d435FL_depth_frame"/>
    <joint name="d435FL_depth_optical_joint" type="fixed">
        <origin rpy="-1.5707963267948966 0 -1.5707963267948966" xyz="0 0 0"/>
        <parent link="d435FL_depth_frame"/>
        <child link="d435FL_depth_optical_frame"/>
    </joint>
    <link name="d435FL_depth_optical_frame"/>
    <gazebo reference="d435FL_link">
        <self_collide>0</self_collide>
        <enable_wind>0</enable_wind>
        <kinematic>0</kinematic>
        <gravity>1</gravity>
        <mu2>1</mu2>
        <fdir1>0 0 0</fdir1>
        <kp>1e+13</kp>
        <kd>1</kd>
        <sensor name="d435FL_depth" type="depth">
            <camera name="d435">
                <horizontal_fov>1.5184364492350666</horizontal_fov>
                <image>
                    <width>424</width>
                    <height>240</height>
                </image>
                <clip>
                    <near>0.05</near>
                    <far>18</far>
                </clip>
            </camera>
            <always_on>1</always_on>
            <update_rate>30</update_rate>
            <visualize>0</visualize>
        </sensor>
    </gazebo>
    <gazebo>
        <plugin filename="librealsense_gazebo_plugin.so" name="d435FL">
            <prefix>d435FL_</prefix>
            <depthUpdateRate>30</depthUpdateRate>
            <depthTopicName>depth/image_raw</depthTopicName>
            <depthCameraInfoTopicName>depth/camera_info</depthCameraInfoTopicName>
            <depthOpticalframeName>d435FL_depth_optical_frame</depthOpticalframeName>
            <rangeMinDepth>0.2</rangeMinDepth>
            <rangeMaxDepth>10.0</rangeMaxDepth>
            <pointCloud>true</pointCloud>
            <pointCloudTopicName>depth/points</pointCloudTopicName>
            <pointCloudCutoff>0.2</pointCloudCutoff>
            <pointCloudCutoffMax>10.0</pointCloudCutoffMax>
        </plugin>
    </gazebo>

    <!-- ****************************************** D435 frontR Camera ******************************************************** -->
    <joint name="d435FR_joint" type="fixed">
        <!-- <origin rpy="1.047 -1.134 -1.571" xyz="-0.124 0.106 -0.223"/> -->
        <origin rpy="1.78339 0.363706 0.54538" xyz="0.487 -0.04 0.063"/>
        <parent link="base"/>
        <child link="d435FR_link"/>
    </joint>
    <link name="d435FR_link">
        <visual>
            <origin rpy="1.5707963267948966 0 1.5707963267948966" xyz="0.0149 -0.0175 0"/>
            <geometry>
                <mesh filename="package://robot_description/wheellegged/WL_P311B/meshes/realsense_d435.stl"/>
            </geometry>
        </visual>
        <collision>
            <origin rpy="0 0 0" xyz="0 -0.0175 0"/>
            <geometry>
                <box size="0.02505 0.09 0.025"/>
            </geometry>
        </collision>
    </link>
    <joint name="d435FR_depth_joint" type="fixed">
        <origin rpy="0 0 0" xyz="0 0 0"/>
        <parent link="d435FR_link"/>
        <child link="d435FR_depth_frame"/>
    </joint>
    <link name="d435FR_depth_frame"/>
    <joint name="d435FR_depth_optical_joint" type="fixed">
        <origin rpy="-1.5707963267948966 0 -1.5707963267948966" xyz="0 0 0"/>
        <parent link="d435FR_depth_frame"/>
        <child link="d435FR_depth_optical_frame"/>
    </joint>
    <link name="d435FR_depth_optical_frame"/>
    <gazebo reference="d435FR_link">
        <self_collide>0</self_collide>
        <enable_wind>0</enable_wind>
        <kinematic>0</kinematic>
        <gravity>1</gravity>
        <mu2>1</mu2>
        <fdir1>0 0 0</fdir1>
        <kp>1e+13</kp>
        <kd>1</kd>
        <sensor name="d435FR_depth" type="depth">
            <camera name="d435">
                <horizontal_fov>1.5184364492350666</horizontal_fov>
                <image>
                    <width>424</width>
                    <height>240</height>
                </image>
                <clip>
                    <near>0.05</near>
                    <far>18</far>
                </clip>
            </camera>
            <always_on>1</always_on>
            <update_rate>30</update_rate>
            <visualize>0</visualize>
        </sensor>
    </gazebo>
    <gazebo>
        <plugin filename="librealsense_gazebo_plugin.so" name="d435FR">
            <prefix>d435FR_</prefix>
            <depthUpdateRate>30</depthUpdateRate>
            <depthTopicName>depth/image_raw</depthTopicName>
            <depthCameraInfoTopicName>depth/camera_info</depthCameraInfoTopicName>
            <depthOpticalframeName>d435FR_depth_optical_frame</depthOpticalframeName>
            <rangeMinDepth>0.2</rangeMinDepth>
            <rangeMaxDepth>10.0</rangeMaxDepth>
            <pointCloud>true</pointCloud>
            <pointCloudTopicName>depth/points</pointCloudTopicName>
            <pointCloudCutoff>0.2</pointCloudCutoff>
            <pointCloudCutoffMax>10.0</pointCloudCutoffMax>
        </plugin>
    </gazebo>
</robot>