<?xml version="1.0"?>

<robot xmlns:xacro="http://www.ros.org/wiki/xacro">

    <xacro:include filename="$(find robot_description)/pointfoot/SF_TRON1B/xacro/transmission.xacro"/>

    <xacro:macro name="leg" params="name mirror mirror_STL *origin">

        <joint name="abad_${name}_joint" type="revolute">
            <origin
                xyz="${abad_offset_x} ${abad_offset_y*mirror} ${abad_offset_z}"
                rpy="0 0 0"/>
            <parent link="base_Link"/>
            <child link="abad_${name}_Link"/>
            <axis xyz="1 0 0"/>
            <dynamics damping="${damping}" friction="${friction}"/>
            <xacro:if value="${(mirror_STL == True)}">
                <limit effort="${abad_torque_max}" velocity="${abad_velocity_max}" lower="${abad_min*PI/180.0}" upper="${abad_max*PI/180.0}"/>
            </xacro:if>
            <xacro:if value="${(mirror_STL == False)}">
                <limit effort="${abad_torque_max}" velocity="${abad_velocity_max}" lower="${-abad_max*PI/180.0}" upper="${-abad_min*PI/180.0}"/>
            </xacro:if>            
        </joint>

        <link name="abad_${name}_Link">
            <visual>
                <origin rpy="0 0 0" xyz="0 0 0"/>
                <geometry>
                    <mesh filename="$(find robot_description)/pointfoot/SF_TRON1B/meshes/abad_${name}_Link.STL" scale="1 1 1"/>
                </geometry>
                <material name="black"/>
            </visual>
            <collision>
                <origin xyz="0.03 0 0" rpy="1.57 0 1.57"/>
                <geometry>
                    <cylinder length="0.05" radius="0.05"/>
                </geometry>
            </collision>
            <inertial>
                <origin rpy="0 0 0" xyz="${abad_com_x} ${abad_com_y*mirror} ${abad_com_z}"/>
                <mass value="${abad_mass}"/>
                <inertia
                    ixx="${abad_ixx}" ixy="${abad_ixy*mirror}" ixz="${abad_ixz}"
                    iyy="${abad_iyy}" iyz="${abad_iyz*mirror}"
                    izz="${abad_izz}"/>       
            </inertial>
        </link>


        <joint name="hip_${name}_joint" type="revolute">
            <origin
                xyz="${hip_offset_x} ${hip_offset_y*mirror} ${hip_offset_z}"
                rpy="0 0 0"/>
            <parent link="abad_${name}_Link"/>
            <child link="hip_${name}_Link"/>
            <axis xyz="0 ${mirror} 0"/>
            <dynamics damping="${damping}" friction="${friction}"/>
            <xacro:if value="${(mirror_STL == True)}">
                <limit effort="${hip_torque_max}" velocity="${hip_velocity_max}" lower="${hip_min*PI/180.0}" upper="${hip_max*PI/180.0}"/>
            </xacro:if>
            <xacro:if value="${(mirror_STL == False)}">
                <limit effort="${hip_torque_max}" velocity="${hip_velocity_max}" lower="${-hip_max*PI/180.0}" upper="${-hip_min*PI/180.0}"/>
            </xacro:if>            
        </joint>

        <link name="hip_${name}_Link">
            <visual>
                <origin rpy="0 0 0" xyz="0 0 0"/>
                <geometry>
                    <mesh filename="$(find robot_description)/pointfoot/SF_TRON1B/meshes/hip_${name}_Link.STL" scale="1 1 1"/>
                </geometry>
                <material name="black"/>
            </visual>
            <inertial>
                <origin rpy="0 0 0" xyz="${hip_com_x} ${hip_com_y*mirror} ${hip_com_z}"/>
                <mass value="${hip_mass}"/>
                <inertia
                    ixx="${hip_ixx}" ixy="${hip_ixy*mirror}" ixz="${hip_ixz}"
                    iyy="${hip_iyy}" iyz="${hip_iyz*mirror}"
                    izz="${hip_izz}"/>       
            </inertial>
        </link>


        <joint name="knee_${name}_joint" type="revolute">
            <origin
                xyz="${knee_offset_x} ${knee_offset_y*mirror} ${knee_offset_z}"
                rpy="0 0 0"/>
            <parent link="hip_${name}_Link"/>
            <child link="knee_${name}_Link"/>
            <axis xyz="0 ${-mirror} 0"/>
            <dynamics damping="${damping}" friction="${friction}"/>
            <xacro:if value="${(mirror_STL == True)}">
                <limit effort="${knee_torque_max}" velocity="${knee_velocity_max}" lower="${knee_min*PI/180.0}" upper="${knee_max*PI/180.0}"/>
            </xacro:if>
            <xacro:if value="${(mirror_STL == False)}">
                <limit effort="${knee_torque_max}" velocity="${knee_velocity_max}" lower="${-knee_max*PI/180.0}" upper="${-knee_min*PI/180.0}"/>
            </xacro:if>            
        </joint>

        <link name="knee_${name}_Link">
            <visual>
                <origin rpy="0 0 0" xyz="0 0 0"/>
                <geometry>
                    <mesh filename="$(find robot_description)/pointfoot/SF_TRON1B/meshes/knee_${name}_Link.STL" scale="1 1 1"/>
                </geometry>
                <material name="black"/>
            </visual>
            <collision>
                <origin rpy="0 0 0" xyz="0 0 0.0"/>
                <geometry>
                    <sphere radius="${calf_radius}"/>
                </geometry>
            </collision>
            <inertial>
                <origin rpy="0 0 0" xyz="${knee_com_x} ${knee_com_y*mirror} ${knee_com_z}"/>
                <mass value="${knee_mass}"/>
                <inertia
                    ixx="${knee_ixx}" ixy="${knee_ixy*mirror}" ixz="${knee_ixz}"
                    iyy="${knee_iyy}" iyz="${knee_iyz*mirror}"
                    izz="${knee_izz}"/>       
            </inertial>
        </link>


        <joint name="ankle_${name}_joint" type="revolute">
            <origin
                xyz="${ankle_offset_x} ${ankle_offset_y*mirror} ${ankle_offset_z}"
                rpy="0 0 0"/>
            <parent link="knee_${name}_Link"/>
            <child link="ankle_${name}_Link"/>
            <axis xyz="0 -1 0"/>
            <dynamics damping="${damping}" friction="${friction}"/>
            <limit effort="${ankle_torque_max}" velocity="${ankle_velocity_max}" lower="${ankle_min*PI/180.0}" upper="${ankle_max*PI/180.0}"/>
        </joint>

        <link name="ankle_${name}_Link">
            <visual>
                <origin rpy="0 0 0" xyz="0 0 0"/>
                <geometry>
                    <mesh filename="$(find robot_description)/pointfoot/SF_TRON1B/meshes/ankle_${name}_Link.STL" scale="1 1 1"/>
                </geometry>
                <material name="grey"/>
            </visual>
            <collision>
                <origin
                        xyz="0 0 0"
                        rpy="0 0 0"/>
                <geometry>
                    <mesh
                            filename="$(find robot_description)/pointfoot/SF_TRON1B/meshes/ankle_${name}_Link.STL"/>
                </geometry>
                <material
                        name="">
                    <color
                            rgba="0.26667 0.26667 0.26667 1"/>
                </material>
            </collision>
            <inertial>
                <origin rpy="0 0 0" xyz="${ankle_com_x} ${ankle_com_y*mirror} ${ankle_com_z}"/>
                <mass value="${ankle_mass}"/>
                <inertia
                    ixx="${ankle_ixx}" ixy="${ankle_ixy*mirror}" ixz="${ankle_ixz}"
                    iyy="${ankle_iyy}" iyz="${ankle_iyz*mirror}"
                    izz="${ankle_izz}"/>       
            </inertial>
        </link>

        <xacro:leg_transmission name="${name}"/>
    </xacro:macro> 
</robot>
