<?xml version="1.0"?>
<!-- =================================================================================== -->
<!-- |    This document was autogenerated by xacro from robot.xacro                    | -->
<!-- |    EDITING THIS FILE BY HAND IS NOT RECOMMENDED                                 | -->
<!-- =================================================================================== -->
<robot name="wheel_legged">
    <material name="black">
        <color rgba="0.0 0.0 0.0 1.0" />
    </material>
    <material name="blue">
        <color rgba="0.0 0.0 0.8 1.0" />
    </material>
    <material name="green">
        <color rgba="0.0 0.8 0.0 1.0" />
    </material>
    <material name="grey">
        <color rgba="0.2 0.2 0.2 1.0" />
    </material>
    <material name="silver">
        <color rgba="0.9137254901960784 0.9137254901960784 0.8470588235294118 1.0" />
    </material>
    <material name="orange">
        <color rgba="1.0 0.4235294117647059 0.0392156862745098 1.0" />
    </material>
    <material name="brown">
        <color rgba="0.8705882352941177 0.8117647058823529 0.7647058823529411 1.0" />
    </material>
    <material name="red">
        <color rgba="0.8 0.0 0.0 1.0" />
    </material>
    <material name="white">
        <color rgba="1.0 1.0 1.0 1.0" />
    </material>
    <gazebo>
        <plugin filename="libwheellegged_hw_sim.so" name="gazebo_ros_control">
            <robotNamespace>/</robotNamespace>
            <robotParam>robot_description</robotParam>
            <robotSimType>wheellegged_gazebo/WheelleggedHWSim</robotSimType>
        </plugin>
    </gazebo>
    <gazebo>
        <plugin filename="libgazebo_ros_p3d.so" name="p3d_base_controller">
            <alwaysOn>true</alwaysOn>
            <updateRate>1000.0</updateRate>
            <bodyName>base</bodyName>
            <topicName>ground_truth/state</topicName>
            <gaussianNoise>0</gaussianNoise>
            <frameName>world</frameName>
            <xyzOffsets>0 0 0</xyzOffsets>
            <rpyOffsets>0 0 0</rpyOffsets>
        </plugin>
    </gazebo>
    <gazebo reference="base_link">
        <maxVel>100.</maxVel>
        <kp>10000.</kp>
        <kd>0.</kd>
    </gazebo>
    <gazebo reference="stick_link">
        <mu1>0.2</mu1>
        <mu2>0.2</mu2>
        <material>Gazebo/White</material>
    </gazebo>
    <!-- LF leg -->
    <gazebo reference="LF_hip">
        <mu1>0.2</mu1>
        <mu2>0.2</mu2>
        <material>Gazebo/DarkGrey</material>
    </gazebo>
    <gazebo reference="LF_thigh">
        <mu1>0.2</mu1>
        <mu2>0.2</mu2>
        <self_collide>0</self_collide>
        <material>Gazebo/DarkGrey</material>
        <kp value="1000000.0" />
        <kd value="1.0" />
    </gazebo>
    <gazebo reference="LF_calf">
        <mu1>0.2</mu1>
        <mu2>0.2</mu2>
        <self_collide>1</self_collide>
    </gazebo>
    <gazebo reference="LF_wheel">
        <mu1>0.6</mu1>
        <mu2>0.6</mu2>
        <self_collide>1</self_collide>
        <material>Gazebo/DarkGrey</material>
        <kp value="1000000.0" />
        <kd value="1.0" />
    </gazebo>
    <gazebo reference="LF_foot">
        <mu1>0.6</mu1>
        <mu2>0.6</mu2>
        <self_collide>0</self_collide>
        <material>Gazebo/White</material>
        <kp value="1000000.0" />
        <kd value="1.0" />
    </gazebo>
    <!-- RF leg -->
    <gazebo reference="RF_hip">
        <mu1>0.2</mu1>
        <mu2>0.2</mu2>
        <material>Gazebo/DarkGrey</material>
    </gazebo>
    <gazebo reference="RF_thigh">
        <mu1>0.2</mu1>
        <mu2>0.2</mu2>
        <self_collide>0</self_collide>
        <material>Gazebo/DarkGrey</material>
        <kp value="1000000.0" />
        <kd value="1.0" />
    </gazebo>
    <gazebo reference="RF_calf">
        <mu1>0.2</mu1>
        <mu2>0.2</mu2>
        <self_collide>1</self_collide>
    </gazebo>
    <gazebo reference="RF_wheel">
        <mu1>0.6</mu1>
        <mu2>0.6</mu2>
        <self_collide>1</self_collide>
        <material>Gazebo/DarkGrey</material>
        <kp value="1000000.0" />
        <kd value="1.0" />
    </gazebo>
    <gazebo reference="RF_foot">
        <mu1>0.6</mu1>
        <mu2>0.6</mu2>
        <self_collide>0</self_collide>
        <material>Gazebo/White</material>
        <kp value="1000000.0" />
        <kd value="1.0" />
    </gazebo>
    <!-- LH leg -->
    <gazebo reference="LH_hip">
        <mu1>0.2</mu1>
        <mu2>0.2</mu2>
        <material>Gazebo/DarkGrey</material>
    </gazebo>
    <gazebo reference="LH_thigh">
        <mu1>0.2</mu1>
        <mu2>0.2</mu2>
        <self_collide>0</self_collide>
        <material>Gazebo/DarkGrey</material>
        <kp value="1000000.0" />
        <kd value="1.0" />
    </gazebo>
    <gazebo reference="LH_calf">
        <mu1>0.2</mu1>
        <mu2>0.2</mu2>
        <self_collide>1</self_collide>
    </gazebo>
    <gazebo reference="LH_wheel">
        <mu1>0.6</mu1>
        <mu2>0.6</mu2>
        <self_collide>1</self_collide>
        <material>Gazebo/DarkGrey</material>
        <kp value="1000000.0" />
        <kd value="1.0" />
    </gazebo>
    <gazebo reference="LH_foot">
        <mu1>0.6</mu1>
        <mu2>0.6</mu2>
        <self_collide>0</self_collide>
        <material>Gazebo/White</material>
        <kp value="1000000.0" />
        <kd value="1.0" />
    </gazebo>
    <!-- RH leg -->
    <gazebo reference="RH_hip">
        <mu1>0.2</mu1>
        <mu2>0.2</mu2>
        <material>Gazebo/DarkGrey</material>
    </gazebo>
    <gazebo reference="RH_thigh">
        <mu1>0.2</mu1>
        <mu2>0.2</mu2>
        <self_collide>0</self_collide>
        <material>Gazebo/DarkGrey</material>
        <kp value="1000000.0" />
        <kd value="1.0" />
    </gazebo>
    <gazebo reference="RH_calf">
        <mu1>0.2</mu1>
        <mu2>0.2</mu2>
        <self_collide>1</self_collide>
    </gazebo>
    <gazebo reference="RH_wheel">
        <mu1>0.6</mu1>
        <mu2>0.6</mu2>
        <self_collide>1</self_collide>
        <material>Gazebo/DarkGrey</material>
        <kp value="1000000.0" />
        <kd value="1.0" />
    </gazebo>
    <gazebo reference="RH_foot">
        <mu1>0.6</mu1>
        <mu2>0.6</mu2>
        <self_collide>0</self_collide>
        <material>Gazebo/White</material>
        <kp value="1000000.0" />
        <kd value="1.0" />
    </gazebo>
    <link name="base">
        <visual>
            <origin rpy="0 0 0" xyz="0 0 -0.045" />
            <geometry>
                <mesh filename="package://robot_description/wheellegged/WL_P311E/meshes/trunk.STL" scale="1 1 1" />
            </geometry>
            <material name="orange">
                <color rgba="0.752941176470588 0.752941176470588 0.752941176470588 1" />
            </material>
        </visual>
        <collision>
            <origin rpy="0 0 0" xyz="-0.0455 0 -0.07551" />
            <geometry>
                <box size="1.064 0.265 0.158" />
            </geometry>
        </collision>
        <inertial>
            <origin rpy="0 0 0" xyz="0.00753 -0.00067 -0.04359" />
            <mass value="23.787" />
            <inertia ixx="0.17222073" ixy="0.00339712" ixz="-0.0092304" iyy="1.15539026" iyz="-0.00099682" izz="1.2147365" />
        </inertial>
    </link>
    <!-- Imu is fixed to the base link -->
    <joint name="limx_imu_joint" type="fixed">
        <origin rpy="0. 0. 0." xyz="0.0 0.0 0.0" />
        <parent link="base" />
        <child link="limx_imu" />
    </joint>
    <!-- Imu link -->
    <link name="limx_imu">
        <inertial>
            <mass value="0.01" />
            <origin rpy="0 0 0" xyz="0 0 0" />
            <inertia ixx="0.000001" ixy="0" ixz="0" iyy="0.000001" iyz="0" izz="0.000001" />
        </inertial>
        <visual>
            <origin rpy="0 0 0" xyz="0 0 0" />
            <geometry>
                <box size="0.015 0.015 0.004" />
            </geometry>
        </visual>
        <material name="orange">
            <color rgba="255 108 10 255" />
        </material>
    </link>
    <gazebo reference="limx_imu">
        <material>Gazebo/Orange</material>
    </gazebo>
    <gazebo reference="limx_imu_joint">
        <disableFixedJointLumping>true</disableFixedJointLumping>
    </gazebo>
    <joint name="LF_HAA" type="revolute">
        <origin rpy="0 0 0" xyz="0.2508 0.065 -0.045" />
        <parent link="base" />
        <child link="LF_hip" />
        <axis xyz="1 0 0" />
        <dynamics damping="0.05" friction="0.01" />
        <limit effort="80" lower="-0.87" upper="0.87" velocity="20" />
    </joint>
    <link name="LF_hip">
        <visual>
            <origin rpy="0 0 0" xyz="0 0 0" />
            <geometry>
                <mesh filename="package://robot_description/wheellegged/WL_P311E/meshes/LF_hip.STL" scale="1 1 1" />
            </geometry>
            <material name="orange" />
            <color rgba="0.8902 0.8902 0.91373 1" />
        </visual>
        <inertial>
            <origin rpy="0 0 0" xyz="0.057951 0.00922 -1.7e-05" />
            <mass value="1.543" />
            <inertia ixx="0.001250053" ixy="-3.0903e-05" ixz="-4.03e-06" iyy="0.002049507" iyz="5.045e-06" izz="0.001568073" />
        </inertial>
    </link>
    <joint name="LF_HFE" type="revolute">
        <origin rpy="0 0 0" xyz="0.064 0.0363 0" />
        <parent link="LF_hip" />
        <child link="LF_thigh" />
        <axis xyz="0 1 0" />
        <dynamics damping="0.05" friction="0.01" />
        <limit effort="80" lower="-2.27" upper="1.22" velocity="20" />
    </joint>
    <link name="LF_thigh">
        <visual>
            <origin rpy="0 0 0" xyz="0 0 0" />
            <geometry>
                <mesh filename="package://robot_description/wheellegged/WL_P311E/meshes/LF_thigh.STL" scale="1 1 1" />
            </geometry>
            <material name="orange" />
            <color rgba="0.8902 0.8902 0.91373 1" />
        </visual>
        <inertial>
            <origin rpy="0 0 0" xyz="-0.061914 0.061328 0.00435" />
            <mass value="2.997" />
            <inertia ixx="0.005164125" ixy="0.00579372" ixz="0.001694032" iyy="0.036812985" iyz="-0.000522747" izz="0.038207062" />
        </inertial>
    </link>
    <joint name="LF_KFE" type="revolute">
        <origin rpy="0 0 0" xyz="-0.28 0.09075 0" />
        <parent link="LF_thigh" />
        <child link="LF_calf" />
        <axis xyz="0 1 0" />
        <dynamics damping="0.05" friction="0.01" />
        <limit effort="80" lower="0" upper="2.0943951023932" velocity="20" />
    </joint>
    <link name="LF_calf">
        <visual>
            <origin rpy="0 0 0" xyz="0 0 0" />
            <geometry>
                <mesh filename="package://robot_description/wheellegged/WL_P311E/meshes/LF_calf.STL" scale="1 1 1" />
            </geometry>
            <material name="orange" />
            <color rgba="0.20392 0.20392 0.20392 1" />
        </visual>
        <collision>
            <origin rpy="0 0.680678408 0" xyz="0.10876 0 -0.08805" />
            <geometry>
                <box size="0.28 0.023 0.0451" />
            </geometry>
        </collision>
        <inertial>
            <origin rpy="0 0 0" xyz="0.175672 0.004984 -0.145368" />
            <mass value="1.405" />
            <inertia ixx="0.006518228" ixy="-0.000248509" ixz="0.006450451" iyy="0.014553507" iyz="0.000233879" izz="0.008539584" />
        </inertial>
    </link>
    <joint name="LF_WHL" type="revolute">
        <origin rpy="0 -0.3 0" xyz="0.21449 0.03459 -0.17998" />
        <parent link="LF_calf" />
        <child link="LF_wheel" />
        <axis xyz="0 1 0" />
        <limit effort="40" lower="-1000" upper="1000" velocity="20" />
        <dynamics friction="1" />
    </joint>
    <link name="LF_wheel">
        <visual>
            <origin rpy="0 0 0" xyz="0 0 0" />
            <geometry>
                <mesh filename="package://robot_description/wheellegged/WL_P311E/meshes/LF_wheel.STL" scale="1 1 1" />
            </geometry>
            <material name="orange" />
            <color rgba="0.69804 0.69804 0.69804 1" />
        </visual>
        <collision>
            <origin rpy="1.5707963267948966 0 0" xyz="0 0 0" />
            <geometry>
                <cylinder length="0.017" radius="0.127" />
            </geometry>
        </collision>
        <inertial>
            <origin rpy="0 0 0" xyz="-3.6e-05 0.000971 -3.9e-05" />
            <mass value="0.995" />
            <inertia ixx="0.004921306" ixy="7e-09" ixz="1.942e-06" iyy="0.009327" iyz="6.3e-08" izz="0.004921781" />
        </inertial>
    </link>
    <joint name="LF_foot_fixed" type="fixed">
        <parent link="LF_wheel" />
        <child link="LF_foot" />
        <origin rpy="0 0 0" xyz="0 0 -0.127" />
    </joint>
    <link name="LF_foot">
        <visual>
            <origin rpy="0 0 0" xyz="0 0 0" />
            <geometry>
                <sphere radius="0.03" />
            </geometry>
        </visual>
    </link>
    <gazebo reference="LF_foot_fixed">
        <disableFixedJointLumping>true</disableFixedJointLumping>
    </gazebo>
    <transmission name="LF_HAA_tran">
        <type>transmission_interface/SimpleTransmission</type>
        <joint name="LF_HAA">
            <hardwareInterface>hardware_interface/EffortJointInterface</hardwareInterface>
        </joint>
        <actuator name="LF_HAA_motor">
            <hardwareInterface>hardware_interface/EffortJointInterface</hardwareInterface>
            <mechanicalReduction>1</mechanicalReduction>
        </actuator>
    </transmission>
    <transmission name="LF_HFE_tran">
        <type>transmission_interface/SimpleTransmission</type>
        <joint name="LF_HFE">
            <hardwareInterface>hardware_interface/EffortJointInterface</hardwareInterface>
        </joint>
        <actuator name="LF_HFE_motor">
            <hardwareInterface>hardware_interface/EffortJointInterface</hardwareInterface>
            <mechanicalReduction>1</mechanicalReduction>
        </actuator>
    </transmission>
    <transmission name="LF_KFE_tran">
        <type>transmission_interface/SimpleTransmission</type>
        <joint name="LF_KFE">
            <hardwareInterface>hardware_interface/EffortJointInterface</hardwareInterface>
        </joint>
        <actuator name="LF_KFE_motor">
            <hardwareInterface>hardware_interface/EffortJointInterface</hardwareInterface>
            <mechanicalReduction>1</mechanicalReduction>
        </actuator>
    </transmission>
    <transmission name="LF_WHL_tran">
        <type>transmission_interface/SimpleTransmission</type>
        <joint name="LF_WHL">
            <hardwareInterface>hardware_interface/EffortJointInterface</hardwareInterface>
        </joint>
        <actuator name="LF_WHL_motor">
            <hardwareInterface>hardware_interface/EffortJointInterface</hardwareInterface>
            <mechanicalReduction>1</mechanicalReduction>
        </actuator>
    </transmission>
    <joint name="RF_HAA" type="revolute">
        <origin rpy="0 0 0" xyz="0.2508 -0.065 -0.045" />
        <parent link="base" />
        <child link="RF_hip" />
        <axis xyz="1 0 0" />
        <dynamics damping="0.05" friction="0.01" />
        <limit effort="80" lower="-0.87" upper="0.87" velocity="20" />
    </joint>
    <link name="RF_hip">
        <visual>
            <origin rpy="0 0 0" xyz="0 0 0" />
            <geometry>
                <mesh filename="package://robot_description/wheellegged/WL_P311E/meshes/RF_hip.STL" scale="1 1 1" />
            </geometry>
            <material name="orange" />
            <color rgba="0.8902 0.8902 0.91373 1" />
        </visual>
        <inertial>
            <origin rpy="0 0 0" xyz="0.057951 -0.00922 -1.7e-05" />
            <mass value="1.543" />
            <inertia ixx="0.001250053" ixy="3.0903e-05" ixz="-4.03e-06" iyy="0.002049507" iyz="-5.045e-06" izz="0.001568073" />
        </inertial>
    </link>
    <joint name="RF_HFE" type="revolute">
        <origin rpy="0 0 0" xyz="0.064 -0.0363 0" />
        <parent link="RF_hip" />
        <child link="RF_thigh" />
        <axis xyz="0 1 0" />
        <dynamics damping="0.05" friction="0.01" />
        <limit effort="80" lower="-2.27" upper="1.22" velocity="20" />
    </joint>
    <link name="RF_thigh">
        <visual>
            <origin rpy="0 0 0" xyz="0 0 0" />
            <geometry>
                <mesh filename="package://robot_description/wheellegged/WL_P311E/meshes/RF_thigh.STL" scale="1 1 1" />
            </geometry>
            <material name="orange" />
            <color rgba="0.8902 0.8902 0.91373 1" />
        </visual>
        <inertial>
            <origin rpy="0 0 0" xyz="-0.061914 -0.061328 0.00435" />
            <mass value="2.997" />
            <inertia ixx="0.005164125" ixy="-0.00579372" ixz="0.001694032" iyy="0.036812985" iyz="0.000522747" izz="0.038207062" />
        </inertial>
    </link>
    <joint name="RF_KFE" type="revolute">
        <origin rpy="0 0 0" xyz="-0.28 -0.09075 0" />
        <parent link="RF_thigh" />
        <child link="RF_calf" />
        <axis xyz="0 1 0" />
        <dynamics damping="0.05" friction="0.01" />
        <limit effort="80" lower="0" upper="2.0943951023932" velocity="20" />
    </joint>
    <link name="RF_calf">
        <visual>
            <origin rpy="0 0 0" xyz="0 0 0" />
            <geometry>
                <mesh filename="package://robot_description/wheellegged/WL_P311E/meshes/RF_calf.STL" scale="1 1 1" />
            </geometry>
            <material name="orange" />
            <color rgba="0.20392 0.20392 0.20392 1" />
        </visual>
        <collision>
            <origin rpy="0 0.680678408 0" xyz="0.10876 0 -0.08805" />
            <geometry>
                <box size="0.28 0.023 0.0451" />
            </geometry>
        </collision>
        <inertial>
            <origin rpy="0 0 0" xyz="0.175672 -0.004984 -0.145368" />
            <mass value="1.405" />
            <inertia ixx="0.006518228" ixy="0.000248509" ixz="0.006450451" iyy="0.014553507" iyz="-0.000233879" izz="0.008539584" />
        </inertial>
    </link>
    <joint name="RF_WHL" type="revolute">
        <origin rpy="0 -0.3 0" xyz="0.21449 -0.03459 -0.17998" />
        <parent link="RF_calf" />
        <child link="RF_wheel" />
        <axis xyz="0 1 0" />
        <limit effort="40" lower="-1000" upper="1000" velocity="20" />
        <dynamics friction="1" />
    </joint>
    <link name="RF_wheel">
        <visual>
            <origin rpy="0 0 0" xyz="0 0 0" />
            <geometry>
                <mesh filename="package://robot_description/wheellegged/WL_P311E/meshes/RF_wheel.STL" scale="1 1 1" />
            </geometry>
            <material name="orange" />
            <color rgba="0.69804 0.69804 0.69804 1" />
        </visual>
        <collision>
            <origin rpy="1.5707963267948966 0 0" xyz="0 0 0" />
            <geometry>
                <cylinder length="0.017" radius="0.127" />
            </geometry>
        </collision>
        <inertial>
            <origin rpy="0 0 0" xyz="-3.6e-05 -0.000971 -3.9e-05" />
            <mass value="0.995" />
            <inertia ixx="0.004921306" ixy="-7e-09" ixz="1.942e-06" iyy="0.009327" iyz="-6.3e-08" izz="0.004921781" />
        </inertial>
    </link>
    <joint name="RF_foot_fixed" type="fixed">
        <parent link="RF_wheel" />
        <child link="RF_foot" />
        <origin rpy="0 0 0" xyz="0 0 -0.127" />
    </joint>
    <link name="RF_foot">
        <visual>
            <origin rpy="0 0 0" xyz="0 0 0" />
            <geometry>
                <sphere radius="0.03" />
            </geometry>
        </visual>
    </link>
    <gazebo reference="RF_foot_fixed">
        <disableFixedJointLumping>true</disableFixedJointLumping>
    </gazebo>
    <transmission name="RF_HAA_tran">
        <type>transmission_interface/SimpleTransmission</type>
        <joint name="RF_HAA">
            <hardwareInterface>hardware_interface/EffortJointInterface</hardwareInterface>
        </joint>
        <actuator name="RF_HAA_motor">
            <hardwareInterface>hardware_interface/EffortJointInterface</hardwareInterface>
            <mechanicalReduction>1</mechanicalReduction>
        </actuator>
    </transmission>
    <transmission name="RF_HFE_tran">
        <type>transmission_interface/SimpleTransmission</type>
        <joint name="RF_HFE">
            <hardwareInterface>hardware_interface/EffortJointInterface</hardwareInterface>
        </joint>
        <actuator name="RF_HFE_motor">
            <hardwareInterface>hardware_interface/EffortJointInterface</hardwareInterface>
            <mechanicalReduction>1</mechanicalReduction>
        </actuator>
    </transmission>
    <transmission name="RF_KFE_tran">
        <type>transmission_interface/SimpleTransmission</type>
        <joint name="RF_KFE">
            <hardwareInterface>hardware_interface/EffortJointInterface</hardwareInterface>
        </joint>
        <actuator name="RF_KFE_motor">
            <hardwareInterface>hardware_interface/EffortJointInterface</hardwareInterface>
            <mechanicalReduction>1</mechanicalReduction>
        </actuator>
    </transmission>
    <transmission name="RF_WHL_tran">
        <type>transmission_interface/SimpleTransmission</type>
        <joint name="RF_WHL">
            <hardwareInterface>hardware_interface/EffortJointInterface</hardwareInterface>
        </joint>
        <actuator name="RF_WHL_motor">
            <hardwareInterface>hardware_interface/EffortJointInterface</hardwareInterface>
            <mechanicalReduction>1</mechanicalReduction>
        </actuator>
    </transmission>
    <joint name="LH_HAA" type="revolute">
        <origin rpy="0 0 0" xyz="-0.2508 0.065 -0.045" />
        <parent link="base" />
        <child link="LH_hip" />
        <axis xyz="1 0 0" />
        <dynamics damping="0.05" friction="0.01" />
        <limit effort="80" lower="-0.87" upper="0.87" velocity="20" />
    </joint>
    <link name="LH_hip">
        <visual>
            <origin rpy="0 0 0" xyz="0 0 0" />
            <geometry>
                <mesh filename="package://robot_description/wheellegged/WL_P311E/meshes/LH_hip.STL" scale="1 1 1" />
            </geometry>
            <material name="orange" />
            <color rgba="0.8902 0.8902 0.91373 1" />
        </visual>
        <inertial>
            <origin rpy="0 0 0" xyz="-0.057951 0.00922 -1.7e-05" />
            <mass value="1.543" />
            <inertia ixx="0.001250053" ixy="3.0903e-05" ixz="4.03e-06" iyy="0.002049507" iyz="5.045e-06" izz="0.001568073" />
        </inertial>
    </link>
    <joint name="LH_HFE" type="revolute">
        <origin rpy="0 0 0" xyz="-0.064 0.0363 0" />
        <parent link="LH_hip" />
        <child link="LH_thigh" />
        <axis xyz="0 1 0" />
        <dynamics damping="0.05" friction="0.01" />
        <limit effort="80" lower="-2.27" upper="1.22" velocity="20" />
    </joint>
    <link name="LH_thigh">
        <visual>
            <origin rpy="0 0 0" xyz="0 0 0" />
            <geometry>
                <mesh filename="package://robot_description/wheellegged/WL_P311E/meshes/LH_thigh.STL" scale="1 1 1" />
            </geometry>
            <material name="orange" />
            <color rgba="0.8902 0.8902 0.91373 1" />
        </visual>
        <inertial>
            <origin rpy="0 0 0" xyz="-0.061914 0.061328 0.00435" />
            <mass value="2.997" />
            <inertia ixx="0.005164125" ixy="0.00579372" ixz="0.001694032" iyy="0.036812985" iyz="-0.000522747" izz="0.038207062" />
        </inertial>
    </link>
    <joint name="LH_KFE" type="revolute">
        <origin rpy="0 0 0" xyz="-0.28 0.09075 0" />
        <parent link="LH_thigh" />
        <child link="LH_calf" />
        <axis xyz="0 1 0" />
        <dynamics damping="0.05" friction="0.01" />
        <limit effort="80" lower="0" upper="2.0943951023932" velocity="20" />
    </joint>
    <link name="LH_calf">
        <visual>
            <origin rpy="0 0 0" xyz="0 0 0" />
            <geometry>
                <mesh filename="package://robot_description/wheellegged/WL_P311E/meshes/LH_calf.STL" scale="1 1 1" />
            </geometry>
            <material name="orange" />
            <color rgba="0.20392 0.20392 0.20392 1" />
        </visual>
        <collision>
            <origin rpy="0 0.680678408 0" xyz="0.10876 0 -0.08805" />
            <geometry>
                <box size="0.28 0.023 0.0451" />
            </geometry>
        </collision>
        <inertial>
            <origin rpy="0 0 0" xyz="0.175672 0.004984 -0.145368" />
            <mass value="1.405" />
            <inertia ixx="0.006518228" ixy="-0.000248509" ixz="0.006450451" iyy="0.014553507" iyz="0.000233879" izz="0.008539584" />
        </inertial>
    </link>
    <joint name="LH_WHL" type="revolute">
        <origin rpy="0 -0.3 0" xyz="0.21449 0.03459 -0.17998" />
        <parent link="LH_calf" />
        <child link="LH_wheel" />
        <axis xyz="0 1 0" />
        <limit effort="40" lower="-1000" upper="1000" velocity="20" />
        <dynamics friction="1" />
    </joint>
    <link name="LH_wheel">
        <visual>
            <origin rpy="0 0 0" xyz="0 0 0" />
            <geometry>
                <mesh filename="package://robot_description/wheellegged/WL_P311E/meshes/LH_wheel.STL" scale="1 1 1" />
            </geometry>
            <material name="orange" />
            <color rgba="0.69804 0.69804 0.69804 1" />
        </visual>
        <collision>
            <origin rpy="1.5707963267948966 0 0" xyz="0 0 0" />
            <geometry>
                <cylinder length="0.017" radius="0.127" />
            </geometry>
        </collision>
        <inertial>
            <origin rpy="0 0 0" xyz="-3.6e-05 0.000971 -3.9e-05" />
            <mass value="0.995" />
            <inertia ixx="0.004921306" ixy="7e-09" ixz="1.942e-06" iyy="0.009327" iyz="6.3e-08" izz="0.004921781" />
        </inertial>
    </link>
    <joint name="LH_foot_fixed" type="fixed">
        <parent link="LH_wheel" />
        <child link="LH_foot" />
        <origin rpy="0 0 0" xyz="0 0 -0.127" />
    </joint>
    <link name="LH_foot">
        <visual>
            <origin rpy="0 0 0" xyz="0 0 0" />
            <geometry>
                <sphere radius="0.03" />
            </geometry>
        </visual>
    </link>
    <gazebo reference="LH_foot_fixed">
        <disableFixedJointLumping>true</disableFixedJointLumping>
    </gazebo>
    <transmission name="LH_HAA_tran">
        <type>transmission_interface/SimpleTransmission</type>
        <joint name="LH_HAA">
            <hardwareInterface>hardware_interface/EffortJointInterface</hardwareInterface>
        </joint>
        <actuator name="LH_HAA_motor">
            <hardwareInterface>hardware_interface/EffortJointInterface</hardwareInterface>
            <mechanicalReduction>1</mechanicalReduction>
        </actuator>
    </transmission>
    <transmission name="LH_HFE_tran">
        <type>transmission_interface/SimpleTransmission</type>
        <joint name="LH_HFE">
            <hardwareInterface>hardware_interface/EffortJointInterface</hardwareInterface>
        </joint>
        <actuator name="LH_HFE_motor">
            <hardwareInterface>hardware_interface/EffortJointInterface</hardwareInterface>
            <mechanicalReduction>1</mechanicalReduction>
        </actuator>
    </transmission>
    <transmission name="LH_KFE_tran">
        <type>transmission_interface/SimpleTransmission</type>
        <joint name="LH_KFE">
            <hardwareInterface>hardware_interface/EffortJointInterface</hardwareInterface>
        </joint>
        <actuator name="LH_KFE_motor">
            <hardwareInterface>hardware_interface/EffortJointInterface</hardwareInterface>
            <mechanicalReduction>1</mechanicalReduction>
        </actuator>
    </transmission>
    <transmission name="LH_WHL_tran">
        <type>transmission_interface/SimpleTransmission</type>
        <joint name="LH_WHL">
            <hardwareInterface>hardware_interface/EffortJointInterface</hardwareInterface>
        </joint>
        <actuator name="LH_WHL_motor">
            <hardwareInterface>hardware_interface/EffortJointInterface</hardwareInterface>
            <mechanicalReduction>1</mechanicalReduction>
        </actuator>
    </transmission>
    <joint name="RH_HAA" type="revolute">
        <origin rpy="0 0 0" xyz="-0.2508 -0.065 -0.045" />
        <parent link="base" />
        <child link="RH_hip" />
        <axis xyz="1 0 0" />
        <dynamics damping="0.05" friction="0.01" />
        <limit effort="80" lower="-0.87" upper="0.87" velocity="20" />
    </joint>
    <link name="RH_hip">
        <visual>
            <origin rpy="0 0 0" xyz="0 0 0" />
            <geometry>
                <mesh filename="package://robot_description/wheellegged/WL_P311E/meshes/RH_hip.STL" scale="1 1 1" />
            </geometry>
            <material name="orange" />
            <color rgba="0.8902 0.8902 0.91373 1" />
        </visual>
        <inertial>
            <origin rpy="0 0 0" xyz="-0.057951 -0.00922 -1.7e-05" />
            <mass value="1.543" />
            <inertia ixx="0.001250053" ixy="-3.0903e-05" ixz="4.03e-06" iyy="0.002049507" iyz="-5.045e-06" izz="0.001568073" />
        </inertial>
    </link>
    <joint name="RH_HFE" type="revolute">
        <origin rpy="0 0 0" xyz="-0.064 -0.0363 0" />
        <parent link="RH_hip" />
        <child link="RH_thigh" />
        <axis xyz="0 1 0" />
        <dynamics damping="0.05" friction="0.01" />
        <limit effort="80" lower="-2.27" upper="1.22" velocity="20" />
    </joint>
    <link name="RH_thigh">
        <visual>
            <origin rpy="0 0 0" xyz="0 0 0" />
            <geometry>
                <mesh filename="package://robot_description/wheellegged/WL_P311E/meshes/RH_thigh.STL" scale="1 1 1" />
            </geometry>
            <material name="orange" />
            <color rgba="0.8902 0.8902 0.91373 1" />
        </visual>
        <inertial>
            <origin rpy="0 0 0" xyz="-0.061914 -0.061328 0.00435" />
            <mass value="2.997" />
            <inertia ixx="0.005164125" ixy="-0.00579372" ixz="0.001694032" iyy="0.036812985" iyz="0.000522747" izz="0.038207062" />
        </inertial>
    </link>
    <joint name="RH_KFE" type="revolute">
        <origin rpy="0 0 0" xyz="-0.28 -0.09075 0" />
        <parent link="RH_thigh" />
        <child link="RH_calf" />
        <axis xyz="0 1 0" />
        <dynamics damping="0.05" friction="0.01" />
        <limit effort="80" lower="0" upper="2.0943951023932" velocity="20" />
    </joint>
    <link name="RH_calf">
        <visual>
            <origin rpy="0 0 0" xyz="0 0 0" />
            <geometry>
                <mesh filename="package://robot_description/wheellegged/WL_P311E/meshes/RH_calf.STL" scale="1 1 1" />
            </geometry>
            <material name="orange" />
            <color rgba="0.20392 0.20392 0.20392 1" />
        </visual>
        <collision>
            <origin rpy="0 0.680678408 0" xyz="0.10876 0 -0.08805" />
            <geometry>
                <box size="0.28 0.023 0.0451" />
            </geometry>
        </collision>
        <inertial>
            <origin rpy="0 0 0" xyz="0.175672 -0.004984 -0.145368" />
            <mass value="1.405" />
            <inertia ixx="0.006518228" ixy="0.000248509" ixz="0.006450451" iyy="0.014553507" iyz="-0.000233879" izz="0.008539584" />
        </inertial>
    </link>
    <joint name="RH_WHL" type="revolute">
        <origin rpy="0 -0.3 0" xyz="0.21449 -0.03459 -0.17998" />
        <parent link="RH_calf" />
        <child link="RH_wheel" />
        <axis xyz="0 1 0" />
        <limit effort="40" lower="-1000" upper="1000" velocity="20" />
        <dynamics friction="1" />
    </joint>
    <link name="RH_wheel">
        <visual>
            <origin rpy="0 0 0" xyz="0 0 0" />
            <geometry>
                <mesh filename="package://robot_description/wheellegged/WL_P311E/meshes/RH_wheel.STL" scale="1 1 1" />
            </geometry>
            <material name="orange" />
            <color rgba="0.69804 0.69804 0.69804 1" />
        </visual>
        <collision>
            <origin rpy="1.5707963267948966 0 0" xyz="0 0 0" />
            <geometry>
                <cylinder length="0.017" radius="0.127" />
            </geometry>
        </collision>
        <inertial>
            <origin rpy="0 0 0" xyz="-3.6e-05 -0.000971 -3.9e-05" />
            <mass value="0.995" />
            <inertia ixx="0.004921306" ixy="-7e-09" ixz="1.942e-06" iyy="0.009327" iyz="-6.3e-08" izz="0.004921781" />
        </inertial>
    </link>
    <joint name="RH_foot_fixed" type="fixed">
        <parent link="RH_wheel" />
        <child link="RH_foot" />
        <origin rpy="0 0 0" xyz="0 0 -0.127" />
    </joint>
    <link name="RH_foot">
        <visual>
            <origin rpy="0 0 0" xyz="0 0 0" />
            <geometry>
                <sphere radius="0.03" />
            </geometry>
        </visual>
    </link>
    <gazebo reference="RH_foot_fixed">
        <disableFixedJointLumping>true</disableFixedJointLumping>
    </gazebo>
    <transmission name="RH_HAA_tran">
        <type>transmission_interface/SimpleTransmission</type>
        <joint name="RH_HAA">
            <hardwareInterface>hardware_interface/EffortJointInterface</hardwareInterface>
        </joint>
        <actuator name="RH_HAA_motor">
            <hardwareInterface>hardware_interface/EffortJointInterface</hardwareInterface>
            <mechanicalReduction>1</mechanicalReduction>
        </actuator>
    </transmission>
    <transmission name="RH_HFE_tran">
        <type>transmission_interface/SimpleTransmission</type>
        <joint name="RH_HFE">
            <hardwareInterface>hardware_interface/EffortJointInterface</hardwareInterface>
        </joint>
        <actuator name="RH_HFE_motor">
            <hardwareInterface>hardware_interface/EffortJointInterface</hardwareInterface>
            <mechanicalReduction>1</mechanicalReduction>
        </actuator>
    </transmission>
    <transmission name="RH_KFE_tran">
        <type>transmission_interface/SimpleTransmission</type>
        <joint name="RH_KFE">
            <hardwareInterface>hardware_interface/EffortJointInterface</hardwareInterface>
        </joint>
        <actuator name="RH_KFE_motor">
            <hardwareInterface>hardware_interface/EffortJointInterface</hardwareInterface>
            <mechanicalReduction>1</mechanicalReduction>
        </actuator>
    </transmission>
    <transmission name="RH_WHL_tran">
        <type>transmission_interface/SimpleTransmission</type>
        <joint name="RH_WHL">
            <hardwareInterface>hardware_interface/EffortJointInterface</hardwareInterface>
        </joint>
        <actuator name="RH_WHL_motor">
            <hardwareInterface>hardware_interface/EffortJointInterface</hardwareInterface>
            <mechanicalReduction>1</mechanicalReduction>
        </actuator>
    </transmission>
</robot>