<?xml version="1.0" encoding="utf-8"?>
<robot name="wheel_biped">
    <!-- 
      Uncomment to support the robot by fixing its base link to the world frame. 
      This anchors the robot in place, preventing movement.
    -->
    
    <!-- 
    <link name="world"/>
    <joint name="base_static_Joint" type="fixed">
        <origin rpy="0 0 0" xyz="0 0 0.3"/>
        <parent link="world"/>
        <child link="base_Link"/>
    </joint>
    -->
    <material name="black">
        <color rgba="0.0 0.0 0.0 1.0"/>
    </material>
    <material name="blue">
        <color rgba="0.0 0.0 0.8 1.0"/>
    </material>
    <material name="green">
        <color rgba="0.0 0.8 0.0 1.0"/>
    </material>
    <material name="grey">
        <color rgba="0.2 0.2 0.2 1.0"/>
    </material>
    <material name="silver">
        <color rgba="0.9137254901960784 0.9137254901960784 0.8470588235294118 1.0"/>
    </material>
    <material name="orange">
        <color rgba="1.0 0.4235294117647059 0.0392156862745098 1.0"/>
    </material>
    <material name="brown">
        <color rgba="0.8705882352941177 0.8117647058823529 0.7647058823529411 1.0"/>
    </material>
    <material name="red">
        <color rgba="0.8 0.0 0.0 1.0"/>
    </material>
    <material name="white">
        <color rgba="1.0 1.0 1.0 1.0"/>
    </material>
    <!-- ros_control plugin -->
    <gazebo>
        <plugin filename="libpointfoot_hw_sim.so" name="gazebo_ros_control">
            <robotNamespace>/</robotNamespace>
            <robotParam>robot_description</robotParam>
            <robotSimType>pointfoot_gazebo/PointFootHWSim</robotSimType>
        </plugin>
    </gazebo>
    <gazebo>
        <plugin filename="libgazebo_ros_p3d.so" name="p3d_base_controller">
            <alwaysOn>true</alwaysOn>
            <updateRate>1000.0</updateRate>
            <bodyName>base_Link</bodyName>
            <topicName>ground_truth/state</topicName>
            <gaussianNoise>0</gaussianNoise>
            <frameName>world</frameName>
            <xyzOffsets>0 0 0</xyzOffsets>
            <rpyOffsets>0 0 0</rpyOffsets>
        </plugin>
    </gazebo>

    <!-- <link name="world"/>
  <joint name="base_static_joint" type="fixed">
    <origin rpy="0 0 0" xyz="0 0 1"/>
    <parent link="world"/>
    <child link="base_Link"/>
  </joint>  -->

    <link
            name="base_Link">
        <inertial>
            <origin rpy="0 0 0" xyz="45.76E-03 0.14E-03 -163.98E-03"/>
            <mass value="9.585"/>
            <inertia ixx="140110.479E-06" ixy="534.939E-06" ixz="28184.116E-06"
                     iyy="110641.449E-06" iyz="-27.278E-06" izz="98944.542E-06"/>
        </inertial>
        <visual>
            <origin
                    xyz="0 0 0"
                    rpy="0 0 0"/>
            <geometry>
                <mesh
                        filename="package://robot_description/pointfoot/WF_TRON1B/meshes/base_Link.STL"/>
            </geometry>
            <material
                    name="">
                <color
                        rgba="0.79216 0.81961 0.93333 1"/>
            </material>
        </visual>
        <collision>
            <origin xyz="0.03 0 -0.072" rpy="0 0 0"/>
            <geometry>
                <box size="0.27 0.26 0.19"/>
            </geometry>
        </collision>
    </link>

     <joint name="limx_imu_joint" type="fixed">
        <origin rpy="0. 0. 0." xyz="0. 0. 0."/>
        <parent link="base_Link"/>
        <child link="limx_imu"/>
    </joint>
    <!-- Imu link -->
    <link name="limx_imu">
        <inertial>
            <mass value="0.01"/>
            <origin rpy="0 0 0" xyz="0 0 0"/>
            <inertia ixx="0.000001" ixy="0" ixz="0" iyy="0.000001" iyz="0" izz="0.000001"/>
        </inertial>
        <visual>
            <origin rpy="0 0 0" xyz="0 0 0"/>
            <geometry>
                <box size="0.015 0.015 0.004"/>
            </geometry>
        </visual>
        <material name="orange">
            <color rgba="255 108 10 255"/>
        </material>
    </link>
    <gazebo reference="limx_imu">
        <material>Gazebo/Orange</material>
    </gazebo>
    <gazebo reference="limx_imu_joint">
        <disableFixedJointLumping>true</disableFixedJointLumping>
    </gazebo>
    
    <link
            name="abad_L_Link">
        <inertial>
            <origin rpy="0 0 0" xyz="-69.77E-03 44.79E-03 0.57E-03"/>
            <mass value="1.469"/>
            <inertia ixx="1555.384E-06" ixy="397.78E-06" ixz="-13.10E-06"
                     iyy="2359.25E-06" iyz="-0.98E-06" izz="2080.92E-06"/>
        </inertial>
        <visual>
            <origin
                    xyz="0 0 0"
                    rpy="0 0 0"/>
            <geometry>
                <mesh
                        filename="package://robot_description/pointfoot/WF_TRON1B/meshes/abad_L_Link.STL"/>
            </geometry>
            <material
                    name="">
                <color
                        rgba="0.79216 0.81961 0.93333 1"/>
            </material>
        </visual>
        <collision>
            <origin xyz="0.03 0 0" rpy="1.57 0 1.57"/>
            <geometry>
                <cylinder length="0.05" radius="0.05"/>
            </geometry>
        </collision>
    </link>
    <joint
            name="abad_L_Joint"
            type="revolute">
        <origin
                xyz="55.56E-03 105E-03 -260.2E-03"
                rpy="0 0 0"/>
        <parent
                link="base_Link"/>
        <child
                link="abad_L_Link"/>
        <axis
                xyz="1 0 0"/>
        <limit effort="80.0" lower="-0.38397" upper="1.39626" velocity="15.0"/>
    </joint>
    <link
            name="hip_L_Link">
        <inertial>
            <origin rpy="0 0 0" xyz="-28.69E-03 -47.7E-03 -39.92E-03"/>
            <mass value="2.3"/>
            <inertia ixx="16937.28E-06" ixy="1647.03E-06" ixz="-9232.53E-06"
                     iyy="22853.28E-06" iyz="2202.40E-06" izz="9334.19E-06"/>
        </inertial>
        <visual>
            <origin
                    xyz="0 0 0"
                    rpy="0 0 0"/>
            <geometry>
                <mesh
                        filename="package://robot_description/pointfoot/WF_TRON1B/meshes/hip_L_Link.STL"/>
            </geometry>
            <material
                    name="">
                <color
                        rgba="1 1 1 1"/>
            </material>
        </visual>
        <collision>
            <origin xyz="-0.10 -0.03 -0.14" rpy="0 0.53 0"/>
            <geometry>
                <cylinder length="0.15" radius="0.035"/>
            </geometry>
        </collision>
    </link>
    <joint
            name="hip_L_Joint"
            type="revolute">
        <origin
                xyz="-0.077 0.02050 0"
                rpy="0 0 0"/>
        <parent
                link="abad_L_Link"/>
        <child
                link="hip_L_Link"/>
        <axis
                xyz="0 1 0"/>
        <limit effort="80.0" lower="-1.012291" upper="1.396263" velocity="15.0"/>
    </joint>
    <link
            name="knee_L_Link">
        <inertial>
            <origin rpy="0 0 0" xyz="119.13E-03 11.06E-03 -203.63E-03"/>
            <mass value="1.49"/>
            <inertia ixx="13232.8E-06" ixy="-435.46E-06" ixz="6935.69E-06"
                     iyy="17661.37E-06" iyz="790.87E-06" izz="5016.98E-06"/>
        </inertial>
        <visual>
            <origin
                    xyz="0 0 0"
                    rpy="0 0 0"/>
            <geometry>
                <mesh
                        filename="package://robot_description/pointfoot/WF_TRON1B/meshes/knee_L_Link.STL"/>
            </geometry>
            <material
                    name="">
                <color
                        rgba="0.79216 0.81961 0.93333 1"/>
            </material>
        </visual>
        <collision>
            <origin xyz="0.078 0 -0.12" rpy="0 -0.55 0"/>
            <geometry>
                <cylinder length="0.26" radius="0.015"/>
            </geometry>
        </collision>
    </link>
    <joint
            name="knee_L_Joint"
            type="revolute">
        <origin
                xyz="-0.1500 -0.02050 -0.25981"
                rpy="0 0 0"/>
        <parent
                link="hip_L_Link"/>
        <child
                link="knee_L_Link"/>
        <axis
                xyz="0 -1 0"/>
        <limit effort="80" lower="-0.872665" upper="1.361357" velocity="15"/>
    </joint>

    <joint name="wheel_L_Joint" type="revolute">
        <origin rpy="0 0 0" xyz="150E-03 43.5E-03 -259.81E-03" />
        <parent link="knee_L_Link" />
        <child link="wheel_L_Link" />
        <axis xyz="0 1 0" />
        <limit effort="40" lower="-1000000" upper="1000000" velocity="40" />
        <dynamics friction="0.01" />
    </joint>

    <link name="wheel_L_Link">
        <visual>
            <origin rpy="0 0 0" xyz="0 0 0" />
            <geometry>
                <mesh filename="package://robot_description/pointfoot/WF_TRON1B/meshes/wheel_L_Link.STL" />
            </geometry>
            <material name="orange" />
            <color rgba="0.69804 0.69804 0.69804 1" />
        </visual>
        <collision>
            <origin rpy="1.5707963267948966 0 0" xyz="0 0.00707 0" />
            <geometry>
                <cylinder length="0.05" radius="0.127" />
            </geometry>
        </collision>
        <inertial>
            <origin rpy="0 0 0" xyz="0.03E-03 8.07E-03 -0.02E-03" />
            <mass value="1.08" />
            <inertia ixx="5155.12E-06" ixy="0.01E-06" ixz="-0.97E-06" 
                     iyy="9742.72E-06" iyz="-0.01E-06" izz="5154.00E-06" />
        </inertial>
    </link>

    <gazebo reference="hip_L_Link">
        <mu1>0.2</mu1>
        <mu2>0.2</mu2>
        <material>Gazebo/DarkGrey</material>
    </gazebo>
    <gazebo reference="knee_L_Link">
        <mu1>0.2</mu1>
        <mu2>0.2</mu2>
        <self_collide>0</self_collide>
        <material>Gazebo/DarkGrey</material>
        <kp value="1000000.0"/>
        <kd value="100.0"/>
    </gazebo>
    <gazebo reference="wheel_L_Link">
        <mu1>0.6</mu1>
        <mu2>0.6</mu2>
        <self_collide>1</self_collide>
        <material>Gazebo/DarkGrey</material>
        <kp value="1000000.0"/>
        <kd value="1.0"/>
    </gazebo>

    <transmission name="abad_L_Joint_tran">
        <type>transmission_interface/SimpleTransmission</type>
        <joint name="abad_L_Joint">
            <hardwareInterface>hardware_interface/EffortJointInterface</hardwareInterface>
        </joint>
        <actuator name="abad_L_Joint_motor">
            <hardwareInterface>hardware_interface/EffortJointInterface</hardwareInterface>
            <mechanicalReduction>1</mechanicalReduction>
        </actuator>
    </transmission>
    <transmission name="hip_L_Joint_tran">
        <type>transmission_interface/SimpleTransmission</type>
        <joint name="hip_L_Joint">
            <hardwareInterface>hardware_interface/EffortJointInterface</hardwareInterface>
        </joint>
        <actuator name="hip_L_Joint_motor">
            <hardwareInterface>hardware_interface/EffortJointInterface</hardwareInterface>
            <mechanicalReduction>1</mechanicalReduction>
        </actuator>
    </transmission>
    <transmission name="knee_L_Joint_tran">
        <type>transmission_interface/SimpleTransmission</type>
        <joint name="knee_L_Joint">
            <hardwareInterface>hardware_interface/EffortJointInterface</hardwareInterface>
        </joint>
        <actuator name="knee_L_Joint_motor">
            <hardwareInterface>hardware_interface/EffortJointInterface</hardwareInterface>
            <mechanicalReduction>1</mechanicalReduction>
        </actuator>
    </transmission>
    <transmission name="wheel_L_Joint_tran">
        <type>transmission_interface/SimpleTransmission</type>
        <joint name="wheel_L_Joint">
            <hardwareInterface>hardware_interface/EffortJointInterface</hardwareInterface>
        </joint>
        <actuator name="wheel_L_Joint_motor">
            <hardwareInterface>hardware_interface/EffortJointInterface</hardwareInterface>
            <mechanicalReduction>1</mechanicalReduction>
        </actuator>
    </transmission>

    <link
            name="abad_R_Link">
        <inertial>
            <origin rpy="0 0 0" xyz="-69.77E-03 -44.79E-03 0.57E-03"/>
            <mass value="1.469"/>
            <inertia ixx="1555.384E-06" ixy="-397.78E-06" ixz="-13.10E-06"
                     iyy="2359.25E-06" iyz="0.98E-06" izz="2080.92E-06"/>
        </inertial>
        <visual>
            <origin
                    xyz="0 0 0"
                    rpy="0 0 0"/>
            <geometry>
                <mesh
                        filename="package://robot_description/pointfoot/WF_TRON1B/meshes/abad_R_Link.STL"/>
            </geometry>
            <material
                    name="">
                <color
                        rgba="0.79216 0.81961 0.93333 1"/>
            </material>
        </visual>
        <collision>
            <origin xyz="0.03 0 0" rpy="1.57 0 1.57"/>
            <geometry>
                <cylinder length="0.05" radius="0.05"/>
            </geometry>
        </collision>
    </link>
    <joint
            name="abad_R_Joint"
            type="revolute">
        <origin
                xyz="55.56E-03 -105E-03 -260.2E-03"
                rpy="0 0 0"/>
        <parent
                link="base_Link"/>
        <child
                link="abad_R_Link"/>
        <axis
                xyz="1 0 0"/>
        <limit effort="80.0" lower="-1.39626" upper="0.38397" velocity="15.0"/>
    </joint>
    <link
            name="hip_R_Link">
        <inertial>
            <origin rpy="0 0 0" xyz="-28.69E-03 47.7E-03 -39.92E-03"/>
            <mass value="2.30"/>
            <inertia ixx="16937.28E-06" ixy="-1647.03E-06" ixz="-9232.53E-06"
                     iyy="22853.28E-06" iyz="-2202.40E-06" izz="9334.19E-06"/>
        </inertial>
        <visual>
            <origin
                    xyz="0 0 0"
                    rpy="0 0 0"/>
            <geometry>
                <mesh
                        filename="package://robot_description/pointfoot/WF_TRON1B/meshes/hip_R_Link.STL"/>
            </geometry>
            <material
                    name="">
                <color
                        rgba="1 1 1 1"/>
            </material>
        </visual>
        <collision>
            <origin xyz="-0.10 0.03 -0.14" rpy="0 0.53 0"/>
            <geometry>
                <cylinder length="0.15" radius="0.035"/>
            </geometry>
        </collision>
    </link>
    <joint
            name="hip_R_Joint"
            type="revolute">
        <origin
                xyz="-0.077 -0.02050 0"
                rpy="0 0 0"/>
        <parent
                link="abad_R_Link"/>
        <child
                link="hip_R_Link"/>
        <axis
                xyz="0 -1 0"/>
        <limit effort="80.0" lower="-1.396263" upper="1.012291" velocity="15.0"/>
    </joint>
    <link
            name="knee_R_Link">
        <inertial>
            <origin rpy="0 0 0" xyz="119.13E-03 -11.06E-03 -203.63E-03"/>
            <mass value="1.49"/>
            <inertia ixx="13232.8E-06" ixy="435.46E-06" ixz="6935.69E-06"
                     iyy="17661.37E-06" iyz="-790.87E-06" izz="5016.98E-06"/>
        </inertial>
        <visual>
            <origin
                    xyz="0 0 0"
                    rpy="0 0 0"/>
            <geometry>
                <mesh
                        filename="package://robot_description/pointfoot/WF_TRON1B/meshes/knee_R_Link.STL"/>
            </geometry>
            <material
                    name="">
                <color
                        rgba="0.79216 0.81961 0.93333 1"/>
            </material>
        </visual>
        <collision>
            <origin xyz="0.078 0 -0.12" rpy="0 -0.55 0"/>
            <geometry>
                <cylinder length="0.26" radius="0.015"/>
            </geometry>
        </collision>
    </link>
    <joint
            name="knee_R_Joint"
            type="revolute">
        <origin
                xyz="-0.1500 0.02050 -0.25981"
                rpy="0 0 0"/>
        <parent
                link="hip_R_Link"/>
        <child
                link="knee_R_Link"/>
        <axis
                xyz="0 1 0"/>
        <limit effort="80" lower="-1.361357" upper="0.872665" velocity="15"/>
    </joint>
    
    <joint name="wheel_R_Joint" type="revolute">
        <origin rpy="0 0 0" xyz="150E-03 -43.5E-03 -259.81E-03" />
        <parent link="knee_R_Link" />
        <child link="wheel_R_Link" />
        <axis xyz="0 1 0" />
        <limit effort="40" lower="-1000000" upper="1000000" velocity="40" />
        <dynamics friction="0.01" />
    </joint>

    <link name="wheel_R_Link">
        <visual>
            <origin rpy="0 0 0" xyz="0 0 0" />
            <geometry>
                <mesh filename="package://robot_description/pointfoot/WF_TRON1B/meshes/wheel_R_Link.STL" />
            </geometry>
            <material name="orange" />
            <color rgba="0.69804 0.69804 0.69804 1" />
        </visual>
        <collision>
            <origin rpy="1.5707963267948966 0 0" xyz="0 -0.00707 0" />
            <geometry>
                <cylinder length="0.05" radius="0.127" />
            </geometry>
        </collision>
        <inertial>
            <origin rpy="0 0 0" xyz="0.03E-03 -8.07E-03 -0.02E-03" />
            <mass value="1.08" />
            <inertia ixx="5155.12E-06" ixy="-0.01E-06" ixz="-0.97E-06" 
                     iyy="9742.72E-06" iyz="0.01E-06" izz="5154.00E-06" />
        </inertial>
    </link>

    <gazebo reference="hip_R_Link">
        <mu1>0.2</mu1>
        <mu2>0.2</mu2>
        <material>Gazebo/DarkGrey</material>
    </gazebo>
    <gazebo reference="knee_R_Link">
        <mu1>0.2</mu1>
        <mu2>0.2</mu2>
        <self_collide>0</self_collide>
        <material>Gazebo/DarkGrey</material>
        <kp value="1000000.0"/>
        <kd value="100.0"/>
    </gazebo>
    <gazebo reference="wheel_R_Link">
        <mu1>0.6</mu1>
        <mu2>0.6</mu2>
        <self_collide>1</self_collide>
        <material>Gazebo/DarkGrey</material>
        <kp value="1000000.0"/>
        <kd value="1.0"/>
    </gazebo>

    <transmission name="abad_R_Joint_tran">
        <type>transmission_interface/SimpleTransmission</type>
        <joint name="abad_R_Joint">
            <hardwareInterface>hardware_interface/EffortJointInterface</hardwareInterface>
        </joint>
        <actuator name="abad_R_Joint_motor">
            <hardwareInterface>hardware_interface/EffortJointInterface</hardwareInterface>
            <mechanicalReduction>1</mechanicalReduction>
        </actuator>
    </transmission>
    <transmission name="hip_R_Joint_tran">
        <type>transmission_interface/SimpleTransmission</type>
        <joint name="hip_R_Joint">
            <hardwareInterface>hardware_interface/EffortJointInterface</hardwareInterface>
        </joint>
        <actuator name="hip_R_Joint_motor">
            <hardwareInterface>hardware_interface/EffortJointInterface</hardwareInterface>
            <mechanicalReduction>1</mechanicalReduction>
        </actuator>
    </transmission>
    <transmission name="knee_R_Joint_tran">
        <type>transmission_interface/SimpleTransmission</type>
        <joint name="knee_R_Joint">
            <hardwareInterface>hardware_interface/EffortJointInterface</hardwareInterface>
        </joint>
        <actuator name="knee_R_Joint_motor">
            <hardwareInterface>hardware_interface/EffortJointInterface</hardwareInterface>
            <mechanicalReduction>1</mechanicalReduction>
        </actuator>
    </transmission>
    <transmission name="wheel_R_Joint_tran">
        <type>transmission_interface/SimpleTransmission</type>
        <joint name="wheel_R_Joint">
            <hardwareInterface>hardware_interface/EffortJointInterface</hardwareInterface>
        </joint>
        <actuator name="wheel_R_Joint_motor">
            <hardwareInterface>hardware_interface/EffortJointInterface</hardwareInterface>
            <mechanicalReduction>1</mechanicalReduction>
        </actuator>
    </transmission>

    <!-- ****************************************** D435 Camera ******************************************************** -->
    <!-- <joint name="d435_joint" type="fixed">
        <origin rpy="0 1.063778179 0" xyz="0.13223 0.0222 -0.26826"/>
        <parent link="base_Link"/>
        <child link="d435_Link"/>
    </joint>
    <link name="d435_Link">
        <visual>
            <origin rpy="1.5707963267948966 0 1.5707963267948966" xyz="0.0149 -0.0175 0"/>
            <geometry>
                <mesh filename="package://robot_description/pointfoot/meshes_camera/d435.dae"/>
            </geometry>
        </visual>
        <collision>
            <origin rpy="0 0 0" xyz="0 -0.0175 0"/>
            <geometry>
                <box size="0.02505 0.09 0.025"/>
            </geometry>
        </collision>
    </link> -->
    <!-- ****************************************** D435 Camera END ******************************************************** -->
</robot>