<?xml version="1.0" encoding="utf-8"?>
<robot name="point_foot">
    <!-- 
      Uncomment to support the robot by fixing its base link to the world frame. 
      This anchors the robot in place, preventing movement.
    -->
    
    <!-- 
    <link name="world"/>
    <joint name="base_static_Joint" type="fixed">
        <origin rpy="0 0 0" xyz="0 0 0.3"/>
        <parent link="world"/>
        <child link="base_Link"/>
    </joint>
    -->

    <material name="black">
        <color rgba="0.0 0.0 0.0 1.0"/>
    </material>
    <material name="blue">
        <color rgba="0.0 0.0 0.8 1.0"/>
    </material>
    <material name="green">
        <color rgba="0.0 0.8 0.0 1.0"/>
    </material>
    <material name="grey">
        <color rgba="0.2 0.2 0.2 1.0"/>
    </material>
    <material name="silver">
        <color rgba="0.9137254901960784 0.9137254901960784 0.8470588235294118 1.0"/>
    </material>
    <material name="orange">
        <color rgba="1.0 0.4235294117647059 0.0392156862745098 1.0"/>
    </material>
    <material name="brown">
        <color rgba="0.8705882352941177 0.8117647058823529 0.7647058823529411 1.0"/>
    </material>
    <material name="red">
        <color rgba="0.8 0.0 0.0 1.0"/>
    </material>
    <material name="white">
        <color rgba="1.0 1.0 1.0 1.0"/>
    </material>
    <!-- ros_control plugin -->
    <gazebo>
        <plugin filename="libpointfoot_hw_sim.so" name="gazebo_ros_control">
            <robotNamespace>/</robotNamespace>
            <robotParam>robot_description</robotParam>
            <robotSimType>pointfoot_gazebo/PointFootHWSim</robotSimType>
        </plugin>
    </gazebo>
    <gazebo>
        <plugin filename="libgazebo_ros_p3d.so" name="p3d_base_controller">
            <alwaysOn>true</alwaysOn>
            <updateRate>1000.0</updateRate>
            <bodyName>base_Link</bodyName>
            <topicName>ground_truth/state</topicName>
            <gaussianNoise>0</gaussianNoise>
            <frameName>world</frameName>
            <xyzOffsets>0 0 0</xyzOffsets>
            <rpyOffsets>0 0 0</rpyOffsets>
        </plugin>
    </gazebo>
    <link
            name="base_Link">
        <inertial>
            <origin rpy="0 0 0" xyz="0.028223 0.004612 0.009378"/>
            <mass value="9.567"/>
            <inertia ixx="0.136700555" ixy="-0.000114115" ixz="0.029870339"
                     iyy="0.111197923" iyz="0.000177889" izz="0.098252391"/>
        </inertial>
        <visual>
            <origin
                    xyz="0 0 0"
                    rpy="0 0 0"/>
            <geometry>
                <mesh
                        filename="../meshes/base_Link.STL"/>
            </geometry>
            <material
                    name="">
                <color
                        rgba="0.79216 0.81961 0.93333 1"/>
            </material>
        </visual>
        <collision>
            <origin xyz="0.01 0 0.1" rpy="0 0 0"/>
            <geometry>
                <box size="0.25 0.26 0.18"/>
            </geometry>
        </collision>
    </link>
    <joint name="limx_imu_joint" type="fixed">
        <origin rpy="0. 0. 0." xyz="0. 0. 0."/>
        <parent link="base_Link"/>
        <child link="limx_imu"/>
    </joint>
    <!-- Imu link -->
    <link name="limx_imu">
        <inertial>
            <mass value="0.01"/>
            <origin rpy="0 0 0" xyz="0 0 0"/>
            <inertia ixx="0.000001" ixy="0" ixz="0" iyy="0.000001" iyz="0" izz="0.000001"/>
        </inertial>
        <visual>
            <origin rpy="0 0 0" xyz="0 0 0"/>
            <geometry>
                <box size="0.015 0.015 0.004"/>
            </geometry>
        </visual>
        <material name="orange">
            <color rgba="255 108 10 255"/>
        </material>
    </link>
    <gazebo reference="limx_imu">
        <material>Gazebo/Orange</material>
    </gazebo>
    <gazebo reference="limx_imu_joint">
        <disableFixedJointLumping>true</disableFixedJointLumping>
    </gazebo>
    <link
            name="abad_L_Link">
        <inertial>
            <origin rpy="0 0 0" xyz="-0.067703 0.044697 0.000863"/>
            <mass value="1.560"/>
            <inertia ixx="0.001629229" ixy="0.000403724" ixz="-0.000022335"
                     iyy="0.002582247" iyz="-0.000005974" izz="0.002247738"/>
        </inertial>
        <visual>
            <origin
                    xyz="0 0 0"
                    rpy="0 0 0"/>
            <geometry>
                <mesh
                        filename="../meshes/abad_L_Link.STL"/>
            </geometry>
            <material
                    name="">
                <color
                        rgba="0.79216 0.81961 0.93333 1"/>
            </material>
        </visual>
        <collision>
            <origin xyz="-0.08 0 0" rpy="1.57 0 0"/>
            <geometry>
                <cylinder length="0.05" radius="0.05"/>
            </geometry>
        </collision>
    </link>
    <joint
            name="abad_L_Joint"
            type="revolute">
        <origin
                xyz="0.039 0.1095 -0.08725"
                rpy="0 0 0"/>
        <parent
                link="base_Link"/>
        <child
                link="abad_L_Link"/>
        <axis
                xyz="1 0 0"/>
        <limit effort="80.0" lower="-0.38397" upper="1.39626" velocity="15.0"/>
    </joint>
    <link
            name="hip_L_Link">
        <inertial>
            <origin rpy="0 0 0" xyz="-0.031048 -0.047035 -0.04462"/>
            <mass value="2.388"/>
            <inertia ixx="0.020018453" ixy="0.001830763" ixz="-0.010975515"
                     iyy="0.026990319" iyz="0.002516115" izz="0.010518009"/>
        </inertial>
        <visual>
            <origin
                    xyz="0 0 0"
                    rpy="0 0 0"/>
            <geometry>
                <mesh
                        filename="../meshes/hip_L_Link.STL"/>
            </geometry>
            <material
                    name="">
                <color
                        rgba="1 1 1 1"/>
            </material>
        </visual>
        <collision>
            <origin xyz="-0.10 -0.02 -0.14" rpy="0 0.53 0"/>
            <geometry>
                <cylinder length="0.18" radius="0.035"/>
            </geometry>
        </collision>
    </link>
    <joint
            name="hip_L_Joint"
            type="revolute">
        <origin
                xyz="-0.077 0.02050 0"
                rpy="0 0 0"/>
        <parent
                link="abad_L_Link"/>
        <child
                link="hip_L_Link"/>
        <axis
                xyz="0 1 0"/>
        <limit effort="80.0" lower="-1.012291" upper="1.396263" velocity="15.0"/>
    </joint>
    <link
            name="knee_L_Link">
        <inertial>
            <origin rpy="0 0 0" xyz="0.05738 0.00164 -0.090403"/>
            <mass value="0.496"/>
            <inertia ixx="0.002548881" ixy="-0.000002869" ixz="0.001577485"
                     iyy="0.003635981" iyz="0.000001051" izz="0.001160832"/>
        </inertial>
        <visual>
            <origin
                    xyz="0 0 0"
                    rpy="0 0 0"/>
            <geometry>
                <mesh
                        filename="../meshes/knee_L_Link.STL"/>
            </geometry>
            <material
                    name="">
                <color
                        rgba="0.79216 0.81961 0.93333 1"/>
            </material>
        </visual>
        <collision>
            <origin xyz="0.078 0 -0.12" rpy="0 -0.55 0"/>
            <geometry>
                <cylinder length="0.26" radius="0.015"/>
            </geometry>
        </collision>
    </link>
    <joint
            name="knee_L_Joint"
            type="revolute">
        <origin
                xyz="-0.1500 -0.02050 -0.25981"
                rpy="0 0 0"/>
        <parent
                link="hip_L_Link"/>
        <child
                link="knee_L_Link"/>
        <axis
                xyz="0 -1 0"/>
        <limit effort="80" lower="-0.872665" upper="1.361357" velocity="15"/>
    </joint>
    <link
            name="foot_L_Link">
        <inertial>
            <origin rpy="0 0 0" xyz="-0.001363 -0.000005 0.006305"/>
            <mass value="0.197"/>
            <inertia ixx="0.000106745" ixy="-0.000000034" ixz="0.000006479"
                     iyy="0.000109884" iyz="-0.000000015" izz="0.000081763"/>
        </inertial>
        <visual>
            <origin
                    xyz="0 0 0"
                    rpy="0 0 0"/>
            <geometry>
                <mesh
                        filename="../meshes/foot_L_Link.STL"/>
            </geometry>
            <material
                    name="">
                <color
                        rgba="0.26667 0.26667 0.26667 1"/>
            </material>
        </visual>
        <collision>
            <origin rpy="0 0 0" xyz="0 0 -0.0"/>
            <geometry>
                <sphere radius="0.032"/>
            </geometry>
        </collision>
    </link>
    <joint
            name="foot_L_Joint"
            type="fixed"
            dont_collapse="true">
        <origin
                xyz="0.150 0 -0.25981"
                rpy="0 0 0"/>
        <parent
                link="knee_L_Link"/>
        <child
                link="foot_L_Link"/>
        <axis
                xyz="0 0 0"/>
    </joint>

    <link name="contact_L_Link">
        <inertial>
            <origin xyz="-6.4629E-05 5.464E-05 0.0011936" rpy="0 0 0"/>
            <mass value="1e-6"/>
            <inertia ixx="1e-12" ixy="0" ixz="0" iyy="1e-12" iyz="0" izz="1e-12"/>
        </inertial>
    </link>
    <joint name="contact_L_Joint" type="fixed">
        <origin xyz="0 0 -0.032" rpy="0 0 0"/>
        <parent link="foot_L_Link"/>
        <child link="contact_L_Link"/>
        <axis xyz="0 1 0"/>
        <limit lower="-0" upper="0" effort="60" velocity="50"/>
    </joint>
    <gazebo reference="foot_L_Joint">
        <disableFixedJointLumping>true</disableFixedJointLumping>
    </gazebo>
    <gazebo reference="hip_L_Link">
        <mu1>0.2</mu1>
        <mu2>0.2</mu2>
        <material>Gazebo/DarkGrey</material>
    </gazebo>
    <gazebo reference="knee_L_Link">
        <mu1>0.2</mu1>
        <mu2>0.2</mu2>
        <self_collide>0</self_collide>
        <material>Gazebo/DarkGrey</material>
        <kp value="1000000.0"/>
        <kd value="100.0"/>
    </gazebo>
    <gazebo reference="foot_L_Link">
        <mu1>2.0</mu1>
        <mu2>2.0</mu2>
        <self_collide>1</self_collide>
        <material>Gazebo/DarkGrey</material>
        <kp value="1000000.0"/>
        <kd value="100.0"/>
    </gazebo>
    <transmission name="abad_L_Joint_tran">
        <type>transmission_interface/SimpleTransmission</type>
        <joint name="abad_L_Joint">
            <hardwareInterface>hardware_interface/EffortJointInterface</hardwareInterface>
        </joint>
        <actuator name="abad_L_Joint_motor">
            <hardwareInterface>hardware_interface/EffortJointInterface</hardwareInterface>
            <mechanicalReduction>1</mechanicalReduction>
        </actuator>
    </transmission>
    <transmission name="hip_L_Joint_tran">
        <type>transmission_interface/SimpleTransmission</type>
        <joint name="hip_L_Joint">
            <hardwareInterface>hardware_interface/EffortJointInterface</hardwareInterface>
        </joint>
        <actuator name="hip_L_Joint_motor">
            <hardwareInterface>hardware_interface/EffortJointInterface</hardwareInterface>
            <mechanicalReduction>1</mechanicalReduction>
        </actuator>
    </transmission>
    <transmission name="knee_L_Joint_tran">
        <type>transmission_interface/SimpleTransmission</type>
        <joint name="knee_L_Joint">
            <hardwareInterface>hardware_interface/EffortJointInterface</hardwareInterface>
        </joint>
        <actuator name="knee_L_Joint_motor">
            <hardwareInterface>hardware_interface/EffortJointInterface</hardwareInterface>
            <mechanicalReduction>1</mechanicalReduction>
        </actuator>
    </transmission>
    
    <link
            name="abad_R_Link">
        <inertial>
            <origin rpy="0 0 0" xyz="-0.067703 -0.044697 0.000863"/>
            <mass value="1.560"/>
            <inertia ixx="0.001629229" ixy="-0.000403724" ixz="-0.000022335"
                     iyy="0.002582247" iyz="0.000005974" izz="0.002247738"/>
        </inertial>
        <visual>
            <origin
                    xyz="0 0 0"
                    rpy="0 0 0"/>
            <geometry>
                <mesh
                        filename="../meshes/abad_R_Link.STL"/>
            </geometry>
            <material
                    name="">
                <color
                        rgba="0.79216 0.81961 0.93333 1"/>
            </material>
        </visual>
        <collision>
            <origin xyz="-0.08 0 0" rpy="1.57 0 0"/>
            <geometry>
                <cylinder length="0.05" radius="0.05"/>
            </geometry>
        </collision>
    </link>
    <joint
            name="abad_R_Joint"
            type="revolute">
        <origin
                xyz="0.039 -0.1095 -0.08725"
                rpy="0 0 0"/>
        <parent
                link="base_Link"/>
        <child
                link="abad_R_Link"/>
        <axis
                xyz="1 0 0"/>
        <limit effort="80.0" lower="-1.39626" upper="0.38397" velocity="15.0"/>
    </joint>
    <link
            name="hip_R_Link">
        <inertial>
            <origin rpy="0 0 0" xyz="-0.031048 0.047035 -0.04462"/>
            <mass value="2.388"/>
            <inertia ixx="0.020018453" ixy="-0.001830763" ixz="-0.010975515"
                     iyy="0.026990319" iyz="-0.002516115" izz="0.010518009"/>
        </inertial>
        <visual>
            <origin
                    xyz="0 0 0"
                    rpy="0 0 0"/>
            <geometry>
                <mesh
                        filename="../meshes/hip_R_Link.STL"/>
            </geometry>
            <material
                    name="">
                <color
                        rgba="1 1 1 1"/>
            </material>
        </visual>
        <collision>
            <origin xyz="-0.10 0.02 -0.14" rpy="0 0.53 0"/>
            <geometry>
                <cylinder length="0.18" radius="0.035"/>
            </geometry>
        </collision>
    </link>
    <joint
            name="hip_R_Joint"
            type="revolute">
        <origin
                xyz="-0.077 -0.02050 0"
                rpy="0 0 0"/>
        <parent
                link="abad_R_Link"/>
        <child
                link="hip_R_Link"/>
        <axis
                xyz="0 -1 0"/>
        <limit effort="80.0" lower="-1.396263" upper="1.012291" velocity="15.0"/>
    </joint>
    <link
            name="knee_R_Link">
        <inertial>
            <origin rpy="0 0 0" xyz="0.05738 -0.00164 -0.090403"/>
            <mass value="0.496"/>
            <inertia ixx="0.002548881" ixy="0.000002869" ixz="0.001577485"
                     iyy="0.003635981" iyz="-0.000001051" izz="0.001160832"/>
        </inertial>
        <visual>
            <origin
                    xyz="0 0 0"
                    rpy="0 0 0"/>
            <geometry>
                <mesh
                        filename="../meshes/knee_R_Link.STL"/>
            </geometry>
            <material
                    name="">
                <color
                        rgba="0.79216 0.81961 0.93333 1"/>
            </material>
        </visual>
        <collision>
            <origin xyz="0.078 0 -0.12" rpy="0 -0.55 0"/>
            <geometry>
                <cylinder length="0.26" radius="0.015"/>
            </geometry>
        </collision>
    </link>
    <joint
            name="knee_R_Joint"
            type="revolute">
        <origin
                xyz="-0.1500 0.02050 -0.25981"
                rpy="0 0 0"/>
        <parent
                link="hip_R_Link"/>
        <child
                link="knee_R_Link"/>
        <axis
                xyz="0 1 0"/>
        <limit effort="80" lower="-1.361357" upper="0.872665" velocity="15"/>
    </joint>
    <link
            name="foot_R_Link">
        <inertial>
            <origin rpy="0 0 0" xyz="0.001363 0.000005 0.006305"/>
            <mass value="0.176"/>
            <inertia ixx="0.000106745" ixy="0.000000034" ixz="0.000006479"
                     iyy="0.000109884" iyz="0.000000015" izz="0.000081763"/>
        </inertial>
        <visual>
            <origin
                    xyz="0 0 0"
                    rpy="0 0 0"/>
            <geometry>
                <mesh
                        filename="../meshes/foot_R_Link.STL"/>
            </geometry>
            <material
                    name="">
                <color
                        rgba="0.26667 0.26667 0.26667 1"/>
            </material>
        </visual>
        <collision>
            <origin rpy="0 0 0" xyz="0 0 -0.0"/>
            <geometry>
                <sphere radius="0.032"/>
            </geometry>
        </collision>
    </link>
    <joint
            name="foot_R_Joint"
            type="fixed"
            dont_collapse="true">
        <origin
                xyz="0.150 0 -0.25981"
                rpy="0 0 0"/>
        <parent
                link="knee_R_Link"/>
        <child
                link="foot_R_Link"/>
        <axis
                xyz="0 0 0"/>
    </joint>

    <link name="contact_R_Link">
        <inertial>
            <origin xyz="-6.4629E-05 5.464E-05 0.0011936" rpy="0 0 0"/>
            <mass value="1e-6"/>
            <inertia ixx="1e-12" ixy="0" ixz="0" iyy="1e-12" iyz="0" izz="1e-12"/>
        </inertial>
    </link>
    <joint name="contact_R_Joint" type="fixed">
        <origin xyz="0 0 -0.032" rpy="0 0 0"/>
        <parent link="foot_R_Link"/>
        <child link="contact_R_Link"/>
        <axis xyz="0 1 0"/>
        <limit lower="-0" upper="0" effort="60" velocity="50"/>
    </joint>
    <gazebo reference="foot_R_Joint">
        <disableFixedJointLumping>true</disableFixedJointLumping>
    </gazebo>
    <gazebo reference="hip_R_Link">
        <mu1>0.2</mu1>
        <mu2>0.2</mu2>
        <material>Gazebo/DarkGrey</material>
    </gazebo>
    <gazebo reference="knee_R_Link">
        <mu1>0.2</mu1>
        <mu2>0.2</mu2>
        <self_collide>0</self_collide>
        <material>Gazebo/DarkGrey</material>
        <kp value="1000000.0"/>
        <kd value="100.0"/>
    </gazebo>
    <gazebo reference="foot_R_Link">
        <mu1>2.0</mu1>
        <mu2>2.0</mu2>
        <self_collide>1</self_collide>
        <material>Gazebo/DarkGrey</material>
        <kp value="1000000.0"/>
        <kd value="100.0"/>
    </gazebo>
    <transmission name="abad_R_Joint_tran">
        <type>transmission_interface/SimpleTransmission</type>
        <joint name="abad_R_Joint">
            <hardwareInterface>hardware_interface/EffortJointInterface</hardwareInterface>
        </joint>
        <actuator name="abad_R_Joint_motor">
            <hardwareInterface>hardware_interface/EffortJointInterface</hardwareInterface>
            <mechanicalReduction>1</mechanicalReduction>
        </actuator>
    </transmission>
    <transmission name="hip_R_Joint_tran">
        <type>transmission_interface/SimpleTransmission</type>
        <joint name="hip_R_Joint">
            <hardwareInterface>hardware_interface/EffortJointInterface</hardwareInterface>
        </joint>
        <actuator name="hip_R_Joint_motor">
            <hardwareInterface>hardware_interface/EffortJointInterface</hardwareInterface>
            <mechanicalReduction>1</mechanicalReduction>
        </actuator>
    </transmission>
    <transmission name="knee_R_Joint_tran">
        <type>transmission_interface/SimpleTransmission</type>
        <joint name="knee_R_Joint">
            <hardwareInterface>hardware_interface/EffortJointInterface</hardwareInterface>
        </joint>
        <actuator name="knee_R_Joint_motor">
            <hardwareInterface>hardware_interface/EffortJointInterface</hardwareInterface>
            <mechanicalReduction>1</mechanicalReduction>
        </actuator>
    </transmission>

    <!-- ****************************************** D435 Camera ******************************************************** -->
    <!-- <joint name="d435_joint" type="fixed">
        <origin rpy="0 1.063778179 0" xyz="0.11567 0.0267 -0.09531"/>
        <parent link="base_Link"/>
        <child link="d435_Link"/>
    </joint>
    <link name="d435_Link">
        <visual>
            <origin rpy="1.5707963267948966 0 1.5707963267948966" xyz="0.0149 -0.0175 0"/>
            <geometry>
                <mesh filename="package://robot_description/pointfoot/meshes_camera/d435.dae"/>
            </geometry>
        </visual>
        <collision>
            <origin rpy="0 0 0" xyz="0 -0.0175 0"/>
            <geometry>
                <box size="0.02505 0.09 0.025"/>
            </geometry>
        </collision>
    </link> -->
    <!-- ****************************************** D435 Camera END ******************************************************** -->

</robot>