<?xml version="1.0" encoding="utf-8"?>
<robot name="wheel_biped">

    <link
            name="base_Link">
        <inertial>
            <origin rpy="0 0 0" xyz="45.76E-03 0.14E-03 -163.98E-03"/>
            <mass value="9.585"/>
            <inertia ixx="140110.479E-06" ixy="534.939E-06" ixz="28184.116E-06"
                     iyy="110641.449E-06" iyz="-27.278E-06" izz="98944.542E-06"/>
        </inertial>
        <visual>
            <origin
                    xyz="0 0 0"
                    rpy="0 0 0"/>
            <geometry>
                <mesh
                        filename="../meshes/base_Link.STL"/>
            </geometry>
            <material
                    name="">
                <color
                        rgba="0.79216 0.81961 0.93333 1"/>
            </material>
        </visual>
        <collision>
            <origin xyz="0.03 0 -0.072" rpy="0 0 0"/>
            <geometry>
                <box size="0.27 0.26 0.19"/>
            </geometry>
        </collision>
    </link>
    <link
            name="abad_L_Link">
        <inertial>
            <origin rpy="0 0 0" xyz="-69.77E-03 44.79E-03 0.57E-03"/>
            <mass value="1.496"/>
            <inertia ixx="1555.384E-06" ixy="397.78E-06" ixz="-13.10E-06"
                     iyy="2359.25E-06" iyz="-0.98E-06" izz="2080.92E-06"/>
        </inertial>
        <visual>
            <origin
                    xyz="0 0 0"
                    rpy="0 0 0"/>
            <geometry>
                <mesh
                        filename="../meshes/abad_L_Link.STL"/>
            </geometry>
            <material
                    name="">
                <color
                        rgba="0.79216 0.81961 0.93333 1"/>
            </material>
        </visual>
        <collision>
            <origin xyz="-0.08 0 0" rpy="1.57 0 0"/>
            <geometry>
                <cylinder length="0.05" radius="0.05"/>
            </geometry>
        </collision>
    </link>
    <joint
            name="abad_L_Joint"
            type="revolute">
        <origin
                xyz="55.56E-03 105E-03 -260.2E-03"
                rpy="0 0 0"/>
        <parent
                link="base_Link"/>
        <child
                link="abad_L_Link"/>
        <axis
                xyz="1 0 0"/>
        <limit effort="80.0" lower="-0.38397" upper="1.39626" velocity="20.0"/>
    </joint>
    <link
            name="hip_L_Link">
        <inertial>
            <origin rpy="0 0 0" xyz="-28.69E-03 -47.7E-03 -39.92E-03"/>
            <mass value="2.3"/>
            <inertia ixx="16937.28E-06" ixy="1647.03E-06" ixz="-9232.53E-06"
                     iyy="22853.28E-06" iyz="2202.40E-06" izz="9334.19E-06"/>
        </inertial>
        <visual>
            <origin
                    xyz="0 0 0"
                    rpy="0 0 0"/>
            <geometry>
                <mesh
                        filename="../meshes/hip_L_Link.STL"/>
            </geometry>
            <material
                    name="">
                <color
                        rgba="1 1 1 1"/>
            </material>
        </visual>
        <collision>
            <origin xyz="-0.10 -0.03 -0.14" rpy="0 0.53 0"/>
            <geometry>
                <cylinder length="0.15" radius="0.035"/>
            </geometry>
        </collision>
    </link>
    <joint
            name="hip_L_Joint"
            type="revolute">
        <origin
                xyz="-0.077 0.02050 0"
                rpy="0 0 0"/>
        <parent
                link="abad_L_Link"/>
        <child
                link="hip_L_Link"/>
        <axis
                xyz="0 1 0"/>
        <limit effort="80.0" lower="-1.012291" upper="1.396263" velocity="20.0"/>
    </joint>
    <link
            name="knee_L_Link">
        <inertial>
            <origin rpy="0 0 0" xyz="119.13E-03 11.06E-03 -203.63E-03"/>
            <mass value="1.49"/>
            <inertia ixx="13232.8E-06" ixy="-435.46E-06" ixz="6935.69E-06"
                     iyy="17661.37E-06" iyz="790.87E-06" izz="5016.98E-06"/>
        </inertial>
        <visual>
            <origin
                    xyz="0 0 0"
                    rpy="0 0 0"/>
            <geometry>
                <mesh
                        filename="../meshes/knee_L_Link.STL"/>
            </geometry>
            <material
                    name="">
                <color
                        rgba="0.79216 0.81961 0.93333 1"/>
            </material>
        </visual>
        <collision>
            <origin xyz="0.078 0 -0.12" rpy="0 -0.55 0"/>
            <geometry>
                <cylinder length="0.26" radius="0.015"/>
            </geometry>
        </collision>
    </link>
    <joint
            name="knee_L_Joint"
            type="revolute">
        <origin
                xyz="-0.1500 -0.02050 -0.25981"
                rpy="0 0 0"/>
        <parent
                link="hip_L_Link"/>
        <child
                link="knee_L_Link"/>
        <axis
                xyz="0 -1 0"/>
        <limit effort="80" lower="-0.872665" upper="1.361357" velocity="20"/>
    </joint>

    <joint name="wheel_L_Joint" type="revolute">
        <origin rpy="0 0 0" xyz="150E-03 43.5E-03 -259.81E-03" />
        <parent link="knee_L_Link" />
        <child link="wheel_L_Link" />
        <axis xyz="0 1 0" />
        <limit effort="40" lower="-1000000" upper="1000000" velocity="40" />
        <dynamics friction="0.01" />
    </joint>

    <link name="wheel_L_Link">
        <visual>
            <origin rpy="0 0 0" xyz="0 0 0" />
            <geometry>
                <mesh filename="../meshes/wheel_L_Link.STL" />
            </geometry>
            <material name="orange" />
            <color rgba="0.69804 0.69804 0.69804 1" />
        </visual>
        <collision>
            <origin rpy="1.5707963267948966 0 0" xyz="0 0 0" />
            <geometry>
                <cylinder length="0.05" radius="0.127" />
            </geometry>
        </collision>
        <inertial>
            <origin rpy="0 0 0" xyz="0.03E-03 8.07E-03 -0.02E-03" />
            <mass value="1.08" />
            <inertia ixx="5155.12E-06" ixy="0.01E-06" ixz="-0.97E-06" 
                     iyy="9742.72E-06" iyz="-0.01E-06" izz="5154.00E-06" />
        </inertial>
    </link>

    <link
            name="abad_R_Link">
        <inertial>
            <origin rpy="0 0 0" xyz="-69.77E-03 -44.79E-03 0.57E-03"/>
            <mass value="1.496"/>
            <inertia ixx="1555.384E-06" ixy="-397.78E-06" ixz="-13.10E-06"
                     iyy="2359.25E-06" iyz="0.98E-06" izz="2080.92E-06"/>
        </inertial>
        <visual>
            <origin
                    xyz="0 0 0"
                    rpy="0 0 0"/>
            <geometry>
                <mesh
                        filename="../meshes/abad_R_Link.STL"/>
            </geometry>
            <material
                    name="">
                <color
                        rgba="0.79216 0.81961 0.93333 1"/>
            </material>
        </visual>
        <collision>
            <origin xyz="-0.08 0 0" rpy="1.57 0 0"/>
            <geometry>
                <cylinder length="0.05" radius="0.05"/>
            </geometry>
        </collision>
    </link>
    <joint
            name="abad_R_Joint"
            type="revolute">
        <origin
                xyz="55.56E-03 -105E-03 -260.2E-03"
                rpy="0 0 0"/>
        <parent
                link="base_Link"/>
        <child
                link="abad_R_Link"/>
        <axis
                xyz="1 0 0"/>
        <limit effort="80.0" lower="-1.39626" upper="0.38397" velocity="20.0"/>
    </joint>
    <link
            name="hip_R_Link">
        <inertial>
            <origin rpy="0 0 0" xyz="-28.69E-03 47.7E-03 -39.92E-03"/>
            <mass value="2.30"/>
            <inertia ixx="16937.28E-06" ixy="-1647.03E-06" ixz="-9232.53E-06"
                     iyy="22853.28E-06" iyz="-2202.40E-06" izz="9334.19E-06"/>
        </inertial>
        <visual>
            <origin
                    xyz="0 0 0"
                    rpy="0 0 0"/>
            <geometry>
                <mesh
                        filename="../meshes/hip_R_Link.STL"/>
            </geometry>
            <material
                    name="">
                <color
                        rgba="1 1 1 1"/>
            </material>
        </visual>
        <collision>
            <origin xyz="-0.10 0.03 -0.14" rpy="0 0.53 0"/>
            <geometry>
                <cylinder length="0.15" radius="0.035"/>
            </geometry>
        </collision>
    </link>
    <joint
            name="hip_R_Joint"
            type="revolute">
        <origin
                xyz="-0.077 -0.02050 0"
                rpy="0 0 0"/>
        <parent
                link="abad_R_Link"/>
        <child
                link="hip_R_Link"/>
        <axis
                xyz="0 -1 0"/>
        <limit effort="80.0" lower="-1.396263" upper="1.012291" velocity="20.0"/>
    </joint>
    <link
            name="knee_R_Link">
        <inertial>
            <origin rpy="0 0 0" xyz="119.13E-03 -11.06E-03 -203.63E-03"/>
            <mass value="1.49"/>
            <inertia ixx="13232.8E-06" ixy="435.46E-06" ixz="6935.69E-06"
                     iyy="17661.37E-06" iyz="-790.87E-06" izz="5016.98E-06"/>
        </inertial>
        <visual>
            <origin
                    xyz="0 0 0"
                    rpy="0 0 0"/>
            <geometry>
                <mesh
                        filename="../meshes/knee_R_Link.STL"/>
            </geometry>
            <material
                    name="">
                <color
                        rgba="0.79216 0.81961 0.93333 1"/>
            </material>
        </visual>
        <collision>
            <origin xyz="0.078 0 -0.12" rpy="0 -0.55 0"/>
            <geometry>
                <cylinder length="0.26" radius="0.015"/>
            </geometry>
        </collision>
    </link>
    <joint
            name="knee_R_Joint"
            type="revolute">
        <origin
                xyz="-0.1500 0.02050 -0.25981"
                rpy="0 0 0"/>
        <parent
                link="hip_R_Link"/>
        <child
                link="knee_R_Link"/>
        <axis
                xyz="0 1 0"/>
        <limit effort="80" lower="-1.361357" upper="0.872665" velocity="20"/>
    </joint>
    
    <joint name="wheel_R_Joint" type="revolute">
        <origin rpy="0 0 0" xyz="150E-03 -43.5E-03 -259.81E-03" />
        <parent link="knee_R_Link" />
        <child link="wheel_R_Link" />
        <axis xyz="0 1 0" />
        <limit effort="40" lower="-1000000" upper="1000000" velocity="40" />
        <dynamics friction="0.01" />
    </joint>

    <link name="wheel_R_Link">
        <visual>
            <origin rpy="0 0 0" xyz="0 0 0" />
            <geometry>
                <mesh filename="../meshes/wheel_R_Link.STL" />
            </geometry>
            <material name="orange" />
            <color rgba="0.69804 0.69804 0.69804 1" />
        </visual>
        <collision>
            <origin rpy="1.5707963267948966 0 0" xyz="0 0 0" />
            <geometry>
                <cylinder length="0.05" radius="0.127" />
            </geometry>
        </collision>
        <inertial>
            <origin rpy="0 0 0" xyz="0.03E-03 -8.07E-03 -0.02E-03" />
            <mass value="1.08" />
            <inertia ixx="5155.12E-06" ixy="-0.01E-06" ixz="-0.97E-06" 
                     iyy="9742.72E-06" iyz="0.01E-06" izz="5154.00E-06" />
        </inertial>
    </link>

</robot>