<?xml version="1.0" encoding="utf-8"?>
<robot name="point_foot">
    <!-- 
      Uncomment to support the robot by fixing its base link to the world frame. 
      This anchors the robot in place, preventing movement.
    -->
    
    <!-- 
    <link name="world"/>
    <joint name="base_static_Joint" type="fixed">
        <origin rpy="0 0 0" xyz="0 0 0.3"/>
        <parent link="world"/>
        <child link="base_Link"/>
    </joint>
    -->

    <material name="black">
        <color rgba="0.0 0.0 0.0 1.0"/>
    </material>
    <material name="blue">
        <color rgba="0.0 0.0 0.8 1.0"/>
    </material>
    <material name="green">
        <color rgba="0.0 0.8 0.0 1.0"/>
    </material>
    <material name="grey">
        <color rgba="0.2 0.2 0.2 1.0"/>
    </material>
    <material name="silver">
        <color rgba="0.9137254901960784 0.9137254901960784 0.8470588235294118 1.0"/>
    </material>
    <material name="orange">
        <color rgba="1.0 0.4235294117647059 0.0392156862745098 1.0"/>
    </material>
    <material name="brown">
        <color rgba="0.8705882352941177 0.8117647058823529 0.7647058823529411 1.0"/>
    </material>
    <material name="red">
        <color rgba="0.8 0.0 0.0 1.0"/>
    </material>
    <material name="white">
        <color rgba="1.0 1.0 1.0 1.0"/>
    </material>
    <!-- ros_control plugin -->
    <gazebo>
        <plugin filename="libpointfoot_hw_sim.so" name="gazebo_ros_control">
            <robotNamespace>/</robotNamespace>
            <robotParam>robot_description</robotParam>
            <robotSimType>pointfoot_gazebo/PointFootHWSim</robotSimType>
        </plugin>
    </gazebo>
    <gazebo>
        <plugin filename="libgazebo_ros_p3d.so" name="p3d_base_controller">
            <alwaysOn>true</alwaysOn>
            <updateRate>1000.0</updateRate>
            <bodyName>base_Link</bodyName>
            <topicName>ground_truth/state</topicName>
            <gaussianNoise>0</gaussianNoise>
            <frameName>world</frameName>
            <xyzOffsets>0 0 0</xyzOffsets>
            <rpyOffsets>0 0 0</rpyOffsets>
        </plugin>
    </gazebo>
    <link
            name="base_Link">
        <inertial>
            <origin rpy="0 0 0" xyz="12.4E-03 0.86E-03 -6.41E-03"/>
            <mass value="8.49"/>
            <inertia ixx="114695.78E-06" ixy="300.36E-06" ixz="24869.11E-06"
                     iyy="93374.40E-06" iyz="-412.55E-06" izz="85090.38E-06"/>
        </inertial>
        <visual>
            <origin
                    xyz="0 0 0"
                    rpy="0 0 0"/>
            <geometry>
                <mesh
                        filename="../meshes/base_Link.STL"/>
            </geometry>
            <material
                    name="">
                <color
                        rgba="0.79216 0.81961 0.93333 1"/>
            </material>
        </visual>
        <collision>
            <origin xyz="-0.005 0 0.06969" rpy="0 0 0"/>
            <geometry>
                <box size="0.28 0.24 0.14"/>
            </geometry>
        </collision>
    </link>
    <joint name="limx_imu_joint" type="fixed">
        <origin rpy="0. 0. 0." xyz="0. 0. 0."/>
        <parent link="base_Link"/>
        <child link="limx_imu"/>
    </joint>
    <!-- Imu link -->
    <link name="limx_imu">
        <inertial>
            <mass value="0.01"/>
            <origin rpy="0 0 0" xyz="0 0 0"/>
            <inertia ixx="0.000001" ixy="0" ixz="0" iyy="0.000001" iyz="0" izz="0.000001"/>
        </inertial>
        <visual>
            <origin rpy="0 0 0" xyz="0 0 0"/>
            <geometry>
                <box size="0.015 0.015 0.004"/>
            </geometry>
        </visual>
        <material name="orange">
            <color rgba="255 108 10 255"/>
        </material>
    </link>
    <gazebo reference="limx_imu">
        <material>Gazebo/Orange</material>
    </gazebo>
    <gazebo reference="limx_imu_joint">
        <disableFixedJointLumping>true</disableFixedJointLumping>
    </gazebo>
    <link
            name="abad_L_Link">
        <inertial>
            <origin rpy="0 0 0" xyz="-68.1E-03 45.66E-03 0.85E-03"/>
            <mass value="1.59"/>
            <inertia ixx="1679.15E-06" ixy="404.64E-06" ixz="-8.97E-06"
                     iyy="2576.87E-06" iyz="-18.99E-06" izz="2303.38E-06"/>
        </inertial>
        <visual>
            <origin
                    xyz="0 0 0"
                    rpy="0 0 0"/>
            <geometry>
                <mesh
                        filename="../meshes/abad_L_Link.STL"/>
            </geometry>
            <material
                    name="">
                <color
                        rgba="0.79216 0.81961 0.93333 1"/>
            </material>
        </visual>
        <collision>
            <origin xyz="-0.08 0 0" rpy="1.57 0 0"/>
            <geometry>
                <cylinder length="0.05" radius="0.05"/>
            </geometry>
        </collision>
    </link>
    <joint
            name="abad_L_Joint"
            type="revolute">
        <origin
                xyz="16.2E-03 105E-03 -90.76E-03"
                rpy="0 0 0"/>
        <parent
                link="base_Link"/>
        <child
                link="abad_L_Link"/>
        <axis
                xyz="1 0 0"/>
        <limit effort="80.0" lower="-0.38397" upper="1.39626" velocity="15.0"/>
    </joint>
    <link
            name="hip_L_Link">
        <inertial>
            <origin rpy="0 0 0" xyz="-29.52E-03 -48.11E-03 -42.87E-03"/>
            <mass value="2.39"/>
            <inertia ixx="19453.83E-06" ixy="1843.83E-06" ixz="-10493.91E-06"
                     iyy="25939.08E-06" iyz="2565.29E-06" izz="10237.66E-06"/>
        </inertial>
        <visual>
            <origin
                    xyz="0 0 0"
                    rpy="0 0 0"/>
            <geometry>
                <mesh
                        filename="../meshes/hip_L_Link.STL"/>
            </geometry>
            <material
                    name="">
                <color
                        rgba="1 1 1 1"/>
            </material>
        </visual>
        <collision>
            <origin xyz="-0.10 -0.025 -0.14" rpy="0 0.53 0"/>
            <geometry>
                <cylinder length="0.15" radius="0.025"/>
            </geometry>
        </collision>
    </link>
    <joint
            name="hip_L_Joint"
            type="revolute">
        <origin
                xyz="-77E-03 20.5E-03 0"
                rpy="0 0 0"/>
        <parent
                link="abad_L_Link"/>
        <child
                link="hip_L_Link"/>
        <axis
                xyz="0 1 0"/>
        <limit effort="80.0" lower="-1.012291" upper="1.396263" velocity="15.0"/>
    </joint>
    <link
            name="knee_L_Link">
        <inertial>
            <origin rpy="0 0 0" xyz="57E-03 1.45E-03 -90.82E-03"/>
            <mass value="0.38"/>
            <inertia ixx="2455.61E-06" ixy="-5.55E-06" ixz="1521.44E-06"
                     iyy="3468.19E-06" iyz="7.21E-06" izz="1062.24E-06"/>
        </inertial>
        <visual>
            <origin
                    xyz="0 0 0"
                    rpy="0 0 0"/>
            <geometry>
                <mesh
                        filename="../meshes/knee_L_Link.STL"/>
            </geometry>
            <material
                    name="">
                <color
                        rgba="0.79216 0.81961 0.93333 1"/>
            </material>
        </visual>
        <collision>
            <origin xyz="0.078 0 -0.12" rpy="0 -0.55 0"/>
            <geometry>
                <cylinder length="0.26" radius="0.015"/>
            </geometry>
        </collision>
    </link>
    <joint
            name="knee_L_Joint"
            type="revolute">
        <origin
                xyz="-150E-03 -20.5E-03 -0.25981"
                rpy="0 0 0"/>
        <parent
                link="hip_L_Link"/>
        <child
                link="knee_L_Link"/>
        <axis
                xyz="0 -1 0"/>
        <limit effort="80" lower="-0.872665" upper="1.361357" velocity="15"/>
    </joint>
    <link
            name="foot_L_Link">
        <inertial>
            <origin rpy="0 0 0" xyz="-0.4E-03 0.0 3.62E-03"/>
            <mass value="0.16"/>
            <inertia ixx="79.95E-06" ixy="-0.01E-06" ixz="1.99E-06"
                     iyy="81.55E-06" iyz="-0.07E-06" izz="65.95E-06"/>
        </inertial>
        <visual>
            <origin
                    xyz="0 0 0"
                    rpy="0 0 0"/>
            <geometry>
                <mesh
                        filename="../meshes/foot_L_Link.STL"/>
            </geometry>
            <material
                    name="">
                <color
                        rgba="0.26667 0.26667 0.26667 1"/>
            </material>
        </visual>
        <collision>
            <origin rpy="0 0 0" xyz="0 0 -0.0"/>
            <geometry>
                <sphere radius="0.032"/>
            </geometry>
        </collision>
    </link>
    <joint
            name="foot_L_Joint"
            type="fixed"
            dont_collapse="true">
        <origin
                xyz="0.150 0 -0.2598"
                rpy="0 0 0"/>
        <parent
                link="knee_L_Link"/>
        <child
                link="foot_L_Link"/>
        <axis
                xyz="0 0 0"/>
    </joint>

    <link name="contact_L_Link">
        <inertial>
            <origin xyz="-6.4629E-05 5.464E-05 0.0011936" rpy="0 0 0"/>
            <mass value="1e-6"/>
            <inertia ixx="1e-12" ixy="0" ixz="0" iyy="1e-12" iyz="0" izz="1e-12"/>
        </inertial>
    </link>
    <joint name="contact_L_Joint" type="fixed">
        <origin xyz="0 0 -0.032" rpy="0 0 0"/>
        <parent link="foot_L_Link"/>
        <child link="contact_L_Link"/>
        <axis xyz="0 1 0"/>
        <limit lower="-0" upper="0" effort="60" velocity="50"/>
    </joint>
    <gazebo reference="foot_L_Joint">
        <disableFixedJointLumping>true</disableFixedJointLumping>
    </gazebo>
    <gazebo reference="hip_L_Link">
        <mu1>0.2</mu1>
        <mu2>0.2</mu2>
        <material>Gazebo/DarkGrey</material>
    </gazebo>
    <gazebo reference="knee_L_Link">
        <mu1>0.2</mu1>
        <mu2>0.2</mu2>
        <self_collide>0</self_collide>
        <material>Gazebo/DarkGrey</material>
        <kp value="1000000.0"/>
        <kd value="100.0"/>
    </gazebo>
    <gazebo reference="foot_L_Link">
        <mu1>2.0</mu1>
        <mu2>2.0</mu2>
        <self_collide>1</self_collide>
        <material>Gazebo/DarkGrey</material>
        <kp value="1000000.0"/>
        <kd value="100.0"/>
    </gazebo>
    <transmission name="abad_L_Joint_tran">
        <type>transmission_interface/SimpleTransmission</type>
        <joint name="abad_L_Joint">
            <hardwareInterface>hardware_interface/EffortJointInterface</hardwareInterface>
        </joint>
        <actuator name="abad_L_Joint_motor">
            <hardwareInterface>hardware_interface/EffortJointInterface</hardwareInterface>
            <mechanicalReduction>1</mechanicalReduction>
        </actuator>
    </transmission>
    <transmission name="hip_L_Joint_tran">
        <type>transmission_interface/SimpleTransmission</type>
        <joint name="hip_L_Joint">
            <hardwareInterface>hardware_interface/EffortJointInterface</hardwareInterface>
        </joint>
        <actuator name="hip_L_Joint_motor">
            <hardwareInterface>hardware_interface/EffortJointInterface</hardwareInterface>
            <mechanicalReduction>1</mechanicalReduction>
        </actuator>
    </transmission>
    <transmission name="knee_L_Joint_tran">
        <type>transmission_interface/SimpleTransmission</type>
        <joint name="knee_L_Joint">
            <hardwareInterface>hardware_interface/EffortJointInterface</hardwareInterface>
        </joint>
        <actuator name="knee_L_Joint_motor">
            <hardwareInterface>hardware_interface/EffortJointInterface</hardwareInterface>
            <mechanicalReduction>1</mechanicalReduction>
        </actuator>
    </transmission>
    
    <link
            name="abad_R_Link">
        <inertial>
            <origin rpy="0 0 0" xyz="-68.1E-03 -45.66E-03 0.85E-03"/>
            <mass value="1.59"/>
            <inertia ixx="1679.15E-06" ixy="-404.64E-06" ixz="-8.97E-06"
                     iyy="2576.87E-06" iyz="18.99E-06" izz="2303.38E-06"/>
        </inertial>
        <visual>
            <origin
                    xyz="0 0 0"
                    rpy="0 0 0"/>
            <geometry>
                <mesh
                        filename="../meshes/abad_R_Link.STL"/>
            </geometry>
            <material
                    name="">
                <color
                        rgba="0.79216 0.81961 0.93333 1"/>
            </material>
        </visual>
        <collision>
            <origin xyz="-0.08 0 0" rpy="1.57 0 0"/>
            <geometry>
                <cylinder length="0.05" radius="0.05"/>
            </geometry>
        </collision>
    </link>
    <joint
            name="abad_R_Joint"
            type="revolute">
        <origin
                xyz="16.2E-03 -105E-03 -90.76E-03"
                rpy="0 0 0"/>
        <parent
                link="base_Link"/>
        <child
                link="abad_R_Link"/>
        <axis
                xyz="1 0 0"/>
        <limit effort="80.0" lower="-1.39626" upper="0.38397" velocity="15.0"/>
    </joint>
    <link
            name="hip_R_Link">
        <inertial>
            <origin rpy="0 0 0" xyz="-29.52E-03 48.11E-03 -42.87E-03"/>
            <mass value="2.39"/>
            <inertia ixx="19453.83E-06" ixy="-1843.83E-06" ixz="-10493.91E-06"
                     iyy="25939.08E-06" iyz="-2565.29E-06" izz="10237.66E-06"/>
        </inertial>
        <visual>
            <origin
                    xyz="0 0 0"
                    rpy="0 0 0"/>
            <geometry>
                <mesh
                        filename="../meshes/hip_R_Link.STL"/>
            </geometry>
            <material
                    name="">
                <color
                        rgba="1 1 1 1"/>
            </material>
        </visual>
        <collision>
            <origin xyz="-0.10 0.025 -0.14" rpy="0 0.53 0"/>
            <geometry>
                <cylinder length="0.15" radius="0.025"/>
            </geometry>
        </collision>
    </link>
    <joint
            name="hip_R_Joint"
            type="revolute">
        <origin
                xyz="-77E-03 -20.5E-03 0"
                rpy="0 0 0"/>
        <parent
                link="abad_R_Link"/>
        <child
                link="hip_R_Link"/>
        <axis
                xyz="0 -1 0"/>
        <limit effort="80.0" lower="-1.396263" upper="1.012291" velocity="15.0"/>
    </joint>
    <link
            name="knee_R_Link">
        <inertial>
            <origin rpy="0 0 0" xyz="57E-03 -1.45E-03 -90.82E-03"/>
            <mass value="0.38"/>
            <inertia ixx="2455.61E-06" ixy="5.55E-06" ixz="1521.44E-06"
                     iyy="3468.19E-06" iyz="-7.21E-06" izz="1062.24E-06"/>
        </inertial>
        <visual>
            <origin
                    xyz="0 0 0"
                    rpy="0 0 0"/>
            <geometry>
                <mesh
                        filename="../meshes/knee_R_Link.STL"/>
            </geometry>
            <material
                    name="">
                <color
                        rgba="0.79216 0.81961 0.93333 1"/>
            </material>
        </visual>
        <collision>
            <origin xyz="0.078 0 -0.12" rpy="0 -0.55 0"/>
            <geometry>
                <cylinder length="0.26" radius="0.015"/>
            </geometry>
        </collision>
    </link>
    <joint
            name="knee_R_Joint"
            type="revolute">
        <origin
                xyz="-150E-03 20.5E-03 -0.25981"
                rpy="0 0 0"/>
        <parent
                link="hip_R_Link"/>
        <child
                link="knee_R_Link"/>
        <axis
                xyz="0 1 0"/>
        <limit effort="80" lower="-1.361357" upper="0.872665" velocity="15"/>
    </joint>
    <link
            name="foot_R_Link">
        <inertial>
            <origin rpy="0 0 0" xyz="-0.4E-03 0.0 3.62E-03"/>
            <mass value="0.16"/>
            <inertia ixx="79.95E-06" ixy="0.01E-06" ixz="1.99E-06"
                     iyy="81.55E-06" iyz="0.07E-06" izz="65.95E-06"/>
        </inertial>
        <visual>
            <origin
                    xyz="0 0 0"
                    rpy="0 0 0"/>
            <geometry>
                <mesh
                        filename="../meshes/foot_R_Link.STL"/>
            </geometry>
            <material
                    name="">
                <color
                        rgba="0.26667 0.26667 0.26667 1"/>
            </material>
        </visual>
        <collision>
            <origin rpy="0 0 0" xyz="0 0 -0.0"/>
            <geometry>
                <sphere radius="0.032"/>
            </geometry>
        </collision>
    </link>
    <joint
            name="foot_R_Joint"
            type="fixed"
            dont_collapse="true">
        <origin
                xyz="0.150 0 -0.2598"
                rpy="0 0 0"/>
        <parent
                link="knee_R_Link"/>
        <child
                link="foot_R_Link"/>
        <axis
                xyz="0 0 0"/>
    </joint>

    <link name="contact_R_Link">
        <inertial>
            <origin xyz="-6.4629E-05 5.464E-05 0.0011936" rpy="0 0 0"/>
            <mass value="1e-6"/>
            <inertia ixx="1e-12" ixy="0" ixz="0" iyy="1e-12" iyz="0" izz="1e-12"/>
        </inertial>
    </link>
    <joint name="contact_R_Joint" type="fixed">
        <origin xyz="0 0 -0.032" rpy="0 0 0"/>
        <parent link="foot_R_Link"/>
        <child link="contact_R_Link"/>
        <axis xyz="0 1 0"/>
        <limit lower="-0" upper="0" effort="60" velocity="50"/>
    </joint>
    <gazebo reference="foot_R_Joint">
        <disableFixedJointLumping>true</disableFixedJointLumping>
    </gazebo>
    <gazebo reference="hip_R_Link">
        <mu1>0.2</mu1>
        <mu2>0.2</mu2>
        <material>Gazebo/DarkGrey</material>
    </gazebo>
    <gazebo reference="knee_R_Link">
        <mu1>0.2</mu1>
        <mu2>0.2</mu2>
        <self_collide>0</self_collide>
        <material>Gazebo/DarkGrey</material>
        <kp value="1000000.0"/>
        <kd value="100.0"/>
    </gazebo>
    <gazebo reference="foot_R_Link">
        <mu1>2.0</mu1>
        <mu2>2.0</mu2>
        <self_collide>1</self_collide>
        <material>Gazebo/DarkGrey</material>
        <kp value="1000000.0"/>
        <kd value="100.0"/>
    </gazebo>
    <transmission name="abad_R_Joint_tran">
        <type>transmission_interface/SimpleTransmission</type>
        <joint name="abad_R_Joint">
            <hardwareInterface>hardware_interface/EffortJointInterface</hardwareInterface>
        </joint>
        <actuator name="abad_R_Joint_motor">
            <hardwareInterface>hardware_interface/EffortJointInterface</hardwareInterface>
            <mechanicalReduction>1</mechanicalReduction>
        </actuator>
    </transmission>
    <transmission name="hip_R_Joint_tran">
        <type>transmission_interface/SimpleTransmission</type>
        <joint name="hip_R_Joint">
            <hardwareInterface>hardware_interface/EffortJointInterface</hardwareInterface>
        </joint>
        <actuator name="hip_R_Joint_motor">
            <hardwareInterface>hardware_interface/EffortJointInterface</hardwareInterface>
            <mechanicalReduction>1</mechanicalReduction>
        </actuator>
    </transmission>
    <transmission name="knee_R_Joint_tran">
        <type>transmission_interface/SimpleTransmission</type>
        <joint name="knee_R_Joint">
            <hardwareInterface>hardware_interface/EffortJointInterface</hardwareInterface>
        </joint>
        <actuator name="knee_R_Joint_motor">
            <hardwareInterface>hardware_interface/EffortJointInterface</hardwareInterface>
            <mechanicalReduction>1</mechanicalReduction>
        </actuator>
    </transmission>
</robot>